Workbook

Sheet afstandshouder
A1: _id | B1: available | C1: calculation_type | D1: depth_cm | E1: format | F1: height_cm | G1: name | H1: price_per_meter | I1: price_per_piece | J1: price_per_square_meter | K1: thickness | L1: total_meter_per_rol | M1: unit | N1: width_cm | O1: subtotal
A2: 676521ea5ff93f7b6d3f9219 | B2: 18 | C2: stuk | G2: Zwart draai | I2: 5.68 | K2: 1.5 | M2: stuks | O2: ==B2*I2
A3: 676521ea5ff93f7b6d3f921a | B3: 108 | C3: stuk | G3: Klein | I3: 0.57 | M3: stuks | O3: ==B3*I3
A4: 676521ea5ff93f7b6d3f921b | B4: 123 | C4: stuk | G4: Middel | I4: 0.58 | K4: 0 | M4: stuks | O4: ==B4*I4
A5: 676521ea5ff93f7b6d3f921c | B5: 97 | C5: stuk | G5: Groot | I5: 0.61 | M5: stuks | O5: ==B5*I5
N6: Total | O6: ==SUM(O2:O5)

Sheet hout
A1: _id | B1: available | C1: calculation_type | D1: depth_cm | E1: format | F1: height_cm | G1: name | H1: price_per_meter | I1: price_per_piece | J1: price_per_square_meter | K1: thickness | L1: total_meter_per_rol | M1: unit | N1: width_cm | O1: subtotal
A2: 676521e55ff93f7b6d3f91d9 | B2: 3 | C2: bord | D2: 2 | F2: 7.5 | G2: 410 X 7,5 X 2 | M2: stuks | N2: 410 | O2: ==B2*(N2*F2/10000)*J2
A3: 676521e55ff93f7b6d3f91da | B3: 1 | C3: bord | D3: 6 | F3: 6.5 | G3: 212 X 6,5 X 6 | M3: stuks | N3: 212 | O3: ==B3*(N3*F3/10000)*J3
A4: 676521e55ff93f7b6d3f91db | B4: 1 | C4: bord | D4: 5.5 | F4: 8 | G4: 3 X 8 X 5,5 | M4: stuks | N4: 3 | O4: ==B4*(N4*F4/10000)*J4
A5: 676521e55ff93f7b6d3f91dc | B5: 2 | C5: bord | D5: 8.5 | F5: 9 | G5: 180 X 9 X 8,5 | M5: stuks | N5: 180 | O5: ==B5*(N5*F5/10000)*J5
N6: Total | O6: ==SUM(O2:O5)

Sheet plexi_opaal
A1: _id | B1: available | C1: calculation_type | D1: depth_cm | E1: format | F1: height_cm | G1: name | H1: price_per_meter | I1: price_per_piece | J1: price_per_square_meter | K1: thickness | L1: total_meter_per_rol | M1: unit | N1: width_cm | O1: subtotal
A2: 676521e55ff93f7b6d3f91dd | B2: 1 | C2: bord | F2: 100 | G2: 180 X 100 | J2: 6.19 | K2: 3 | M2: stuks | N2: 180 | O2: ==B2*(N2*F2/10000)*J2
N3: Total | O3: ==SUM(O2:O2)

Sheet forex_zwart
A1: _id | B1: available | C1: calculation_type | D1: depth_cm | E1: format | F1: height_cm | G1: name | H1: price_per_meter | I1: price_per_piece | J1: price_per_square_meter | K1: thickness | L1: total_meter_per_rol | M1: unit | N1: width_cm | O1: subtotal
A2: 676521e25ff93f7b6d3f91b0 | B2: 2 | C2: bord | F2: 100 | G2: 120x100 | J2: 4.76 | K2: 1 | M2: stuks | N2: 120 | O2: ==B2*(N2*F2/10000)*J2
A3: 676521e25ff93f7b6d3f91b1 | B3: 1 | C3: bord | F3: 118 | G3: 122x118 | J3: 4.76 | K3: 4 | M3: stuks | N3: 122 | O3: ==B3*(N3*F3/10000)*J3
A4: 676521e25ff93f7b6d3f91b2 | B4: 1 | C4: bord | F4: 40 | G4: 30 x 40 | J4: 4.76 | M4: stuks | N4: 30 | O4: ==B4*(N4*F4/10000)*J4
A5: 676521e25ff93f7b6d3f91b3 | B5: 1 | C5: bord | F5: 147 | G5: 150x147 | J5: 4.76 | K5: 4 | M5: stuks | N5: 150 | O5: ==B5*(N5*F5/10000)*J5
A6: 676521e25ff93f7b6d3f91b4 | B6: 1 | C6: bord | F6: 42 | G6: 44 x 42 | J6: 4.76 | M6: stuks | N6: 44 | O6: ==B6*(N6*F6/10000)*J6
A7: 676521e25ff93f7b6d3f91b5 | B7: 2 | C7: bord | F7: 18 | G7: 200x18 | J7: 4.76 | K7: 1 | M7: stuks | N7: 200 | O7: ==B7*(N7*F7/10000)*J7
A8: 676521e25ff93f7b6d3f91b6 | B8: 1 | C8: bord | F8: 120 | G8: 204x120 ZW | J8: 4.76 | K8: 4 | M8: stuks | N8: 204 | O8: ==B8*(N8*F8/10000)*J8
A9: 676521e25ff93f7b6d3f91b7 | B9: 1 | C9: bord | F9: 9.5 | G9: 23x9,5 | J9: 4.76 | K9: 4 | M9: stuks | N9: 23 | O9: ==B9*(N9*F9/10000)*J9
A10: 676521e25ff93f7b6d3f91b8 | B10: 1 | C10: bord | F10: 18 | G10: 24 x 18 | J10: 4.76 | K10: 5 | M10: stuks | N10: 24 | O10: ==B10*(N10*F10/10000)*J10
A11: 676521e25ff93f7b6d3f91b9 | B11: 1 | C11: bord | F11: 97 | G11: 24x97 ZW | J11: 4.76 | K11: 5 | M11: stuks | N11: 24 | O11: ==B11*(N11*F11/10000)*J11
A12: 676521e25ff93f7b6d3f91ba | B12: 3 | C12: bord | F12: 30 | G12: 30x30 | J12: 4.76 | K12: 7 | M12: stuks | N12: 30 | O12: ==B12*(N12*F12/10000)*J12
A13: 676521e25ff93f7b6d3f91bb | B13: 8 | C13: bord | F13: 29 | G13: 32x29 | J13: 4.76 | K13: 4 | M13: stuks | N13: 32 | O13: ==B13*(N13*F13/10000)*J13
A14: 676521e35ff93f7b6d3f91bc | B14: 1 | C14: bord | F14: 29 | G14: 34x29 | J14: 4.76 | K14: 5 | M14: stuks | N14: 34 | O14: ==B14*(N14*F14/10000)*J14
A15: 676521e35ff93f7b6d3f91bd | B15: 1 | C15: bord | F15: 18 | G15: 40 x 18 | J15: 4.76 | K15: 5 | M15: stuks | N15: 40 | O15: ==B15*(N15*F15/10000)*J15
A16: 676521e35ff93f7b6d3f91be | B16: 1 | C16: bord | F16: 40 | G16: 40 x 40 | J16: 4.76 | K16: 5 | M16: stuks | N16: 40 | O16: ==B16*(N16*F16/10000)*J16
A17: 676521e35ff93f7b6d3f91bf | B17: 1 | C17: bord | F17: 50 | G17: 47 x 50 | J17: 4.76 | M17: stuks | N17: 47 | O17: ==B17*(N17*F17/10000)*J17
A18: 676521e35ff93f7b6d3f91c0 | B18: 1 | C18: bord | F18: 35 | G18: 93 x 35 | J18: 4.76 | M18: stuks | N18: 93 | O18: ==B18*(N18*F18/10000)*J18
A19: 676521e35ff93f7b6d3f91c1 | B19: 1 | C19: bord | F19: 40 | G19: 100 x 40 | J19: 4.76 | M19: stuks | N19: 100 | O19: ==B19*(N19*F19/10000)*J19
A20: 676521e35ff93f7b6d3f91c2 | B20: 1 | C20: bord | F20: 11 | G20: 53 x 11 | J20: 4.76 | M20: stuks | N20: 53 | O20: ==B20*(N20*F20/10000)*J20
A21: 676521e35ff93f7b6d3f91c3 | B21: 1 | C21: bord | F21: 24 | G21: 97 x 24 | J21: 4.76 | M21: stuks | N21: 97 | O21: ==B21*(N21*F21/10000)*J21
A22: 676521e35ff93f7b6d3f91c4 | B22: 1 | C22: bord | F22: 18 | G22: 50 x 18 | J22: 4.76 | K22: 5 | M22: stuks | N22: 50 | O22: ==B22*(N22*F22/10000)*J22
A23: 676521e35ff93f7b6d3f91c5 | B23: 1 | C23: bord | F23: 50 | G23: 50 x 50 | J23: 4.76 | K23: 2 | M23: stuks | N23: 50 | O23: ==B23*(N23*F23/10000)*J23
A24: 676521e35ff93f7b6d3f91c6 | B24: 1 | C24: bord | F24: 20 | G24: 50x20 | J24: 4.76 | K24: 5 | M24: stuks | N24: 50 | O24: ==B24*(N24*F24/10000)*J24
A25: 676521e35ff93f7b6d3f91c7 | B25: 1 | C25: bord | F25: 123 | G25: 305 x 123 | J25: 4.76 | M25: stuks | N25: 305 | O25: ==B25*(N25*F25/10000)*J25
A26: 676521e35ff93f7b6d3f91c8 | B26: 1 | C26: bord | F26: 100 | G26: 27 x 100 | J26: 4.76 | M26: stuks | N26: 27 | O26: ==B26*(N26*F26/10000)*J26
A27: 676521e45ff93f7b6d3f91c9 | B27: 1 | C27: bord | F27: 22 | G27: 59x22 | J27: 4.76 | K27: 5 | M27: stuks | N27: 59 | O27: ==B27*(N27*F27/10000)*J27
A28: 676521e45ff93f7b6d3f91ca | B28: 3 | C28: bord | F28: 17.5 | G28: 60 x 17,5 | J28: 4.76 | K28: 5 | M28: stuks | N28: 60 | O28: ==B28*(N28*F28/10000)*J28
A29: 676521e45ff93f7b6d3f91cb | B29: 2 | C29: bord | F29: 38 | G29: 60x38 | J29: 4.76 | K29: 8 | M29: stuks | N29: 60 | O29: ==B29*(N29*F29/10000)*J29
A30: 676521e45ff93f7b6d3f91cc | B30: 2 | C30: bord | F30: 60 | G30: 60x60 ZW | J30: 4.76 | K30: 2 | M30: stuks | N30: 60 | O30: ==B30*(N30*F30/10000)*J30
A31: 676521e45ff93f7b6d3f91cd | B31: 1 | C31: bord | F31: 108.5 | G31: 22,5 X 108,5 | J31: 4.76 | M31: stuks | N31: 22.5 | O31: ==B31*(N31*F31/10000)*J31
A32: 676521e45ff93f7b6d3f91ce | B32: 1 | C32: bord | F32: 51 | G32: 80 X 51 | J32: 4.76 | M32: stuks | N32: 80 | O32: ==B32*(N32*F32/10000)*J32
A33: 676521e45ff93f7b6d3f91cf | B33: 1 | C33: bord | F33: 37 | G33: 48,5 x 37 | J33: 4.76 | K33: 5 | M33: stuks | N33: 48.5 | O33: ==B33*(N33*F33/10000)*J33
A34: 676521e45ff93f7b6d3f91d0 | B34: 1 | C34: bord | F34: 72.5 | G34: 137 x 72,5 | J34: 4.76 | K34: 5 | M34: stuks | N34: 137 | O34: ==B34*(N34*F34/10000)*J34
A35: 676521e45ff93f7b6d3f91d1 | B35: 2 | C35: bord | F35: 35 | G35: 72 x 35 | J35: 4.76 | K35: 3 | M35: stuks | N35: 72 | O35: ==B35*(N35*F35/10000)*J35
A36: 676521e45ff93f7b6d3f91d2 | B36: 1 | C36: bord | F36: 24 | G36: 64 X 24@ | J36: 4.76 | K36: 3 | M36: stuks | N36: 64 | O36: ==B36*(N36*F36/10000)*J36
N37: Total | O37: ==SUM(O2:O36)

Sheet forex_wit
A1: _id | B1: available | C1: calculation_type | D1: depth_cm | E1: format | F1: height_cm | G1: name | H1: price_per_meter | I1: price_per_piece | J1: price_per_square_meter | K1: thickness | L1: total_meter_per_rol | M1: unit | N1: width_cm | O1: subtotal
A2: 676521e65ff93f7b6d3f91e3 | B2: 1 | C2: bord | F2: 20 | G2: 50 X 20 | J2: 6.08 | M2: stuks | N2: 50 | O2: ==B2*(N2*F2/10000)*J2
A3: 676521e65ff93f7b6d3f91e4 | B3: 1 | C3: bord | F3: 20 | G3: 122,5 X 20 | J3: 6.08 | M3: stuks | N3: 122.5 | O3: ==B3*(N3*F3/10000)*J3
A4: 676521e65ff93f7b6d3f91e5 | B4: 1 | C4: bord | F4: 29 | G4: 34 X 29 | J4: 6.08 | M4: stuks | N4: 34 | O4: ==B4*(N4*F4/10000)*J4
A5: 676521e65ff93f7b6d3f91e6 | B5: 1 | C5: bord | F5: 29 | G5: 32 X 29 | J5: 6.08 | M5: stuks | N5: 32 | O5: ==B5*(N5*F5/10000)*J5
A6: 676521e65ff93f7b6d3f91e7 | B6: 2 | C6: bord | F6: 29 | G6: 42 x 29 | J6: 6.08 | M6: stuks | N6: 42 | O6: ==B6*(N6*F6/10000)*J6
A7: 676521e65ff93f7b6d3f91e8 | B7: 2 | C7: bord | F7: 60 | G7: 23 x 60 | J7: 6.08 | M7: stuks | N7: 23 | O7: ==B7*(N7*F7/10000)*J7
A8: 676521e65ff93f7b6d3f91e9 | B8: 2 | C8: bord | F8: 22 | G8: 59 x 22 | J8: 6.08 | M8: stuks | N8: 59 | O8: ==B8*(N8*F8/10000)*J8
A9: 676521e65ff93f7b6d3f91ea | B9: 1 | C9: bord | F9: 20 | G9: 50 x 20 | J9: 6.08 | M9: stuks | N9: 50 | O9: ==B9*(N9*F9/10000)*J9
A10: 676521e65ff93f7b6d3f91eb | B10: 1 | C10: bord | F10: 14.5 | G10: 50 x 14,5 | J10: 6.08 | M10: stuks | N10: 50 | O10: ==B10*(N10*F10/10000)*J10
A11: 676521e75ff93f7b6d3f91ec | B11: 2 | C11: bord | F11: 35 | G11: 45 x 35 | J11: 6.08 | K11: 1 | M11: stuks | N11: 45 | O11: ==B11*(N11*F11/10000)*J11
A12: 676521e75ff93f7b6d3f91ed | B12: 1 | C12: bord | F12: 50 | G12: 22,5 x 50 | J12: 6.08 | K12: 1 | M12: stuks | N12: 22.5 | O12: ==B12*(N12*F12/10000)*J12
A13: 676521e75ff93f7b6d3f91ee | B13: 1 | C13: bord | F13: 17.5 | G13: 60 x 17,5 | J13: 6.08 | M13: stuks | N13: 60 | O13: ==B13*(N13*F13/10000)*J13
A14: 676521e75ff93f7b6d3f91ef | B14: 4 | C14: bord | F14: 9.5 | G14: 24 x 9,5 | J14: 6.08 | M14: stuks | N14: 24 | O14: ==B14*(N14*F14/10000)*J14
A15: 676521e75ff93f7b6d3f91f0 | B15: 3 | C15: bord | F15: 15 | G15: 20 x 15 | J15: 6.08 | M15: stuks | N15: 20 | O15: ==B15*(N15*F15/10000)*J15
A16: 676521e75ff93f7b6d3f91f1 | B16: 3 | C16: bord | F16: 18 | G16: 20 x 18 | J16: 6.08 | M16: stuks | N16: 20 | O16: ==B16*(N16*F16/10000)*J16
A17: 676521e75ff93f7b6d3f91f2 | B17: 7 | C17: bord | F17: 18 | G17: 24 x 18 | J17: 6.08 | M17: stuks | N17: 24 | O17: ==B17*(N17*F17/10000)*J17
A18: 676521e75ff93f7b6d3f91f3 | B18: 1 | C18: bord | F18: 22 | G18: 31 x 22 | J18: 6.08 | M18: stuks | N18: 31 | O18: ==B18*(N18*F18/10000)*J18
A19: 676521e75ff93f7b6d3f91f4 | B19: 3 | C19: bord | F19: 30 | G19: 30 x 30 | J19: 6.08 | M19: stuks | N19: 30 | O19: ==B19*(N19*F19/10000)*J19
A20: 676521e75ff93f7b6d3f91f5 | B20: 2 | C20: bord | F20: 50 | G20: 40 x 50 | J20: 6.08 | K20: 8 | M20: stuks | N20: 40 | O20: ==B20*(N20*F20/10000)*J20
A21: 676521e75ff93f7b6d3f91f6 | B21: 0 | C21: bord | F21: 50 | G21: 50 x 50 | J21: 6.08 | K21: 1 | M21: stuks | N21: 50 | O21: ==B21*(N21*F21/10000)*J21
A22: 676521e75ff93f7b6d3f91f7 | B22: 7 | C22: bord | F22: 35.5 | G22: 22,5 x 35,5 | J22: 6.08 | K22: 3 | M22: stuks | N22: 22.5 | O22: ==B22*(N22*F22/10000)*J22
A23: 676521e75ff93f7b6d3f91f8 | B23: 1 | C23: bord | F23: 58 | G23: 28 x 58 | J23: 6.08 | M23: stuks | N23: 28 | O23: ==B23*(N23*F23/10000)*J23
A24: 676521e75ff93f7b6d3f91f9 | B24: 1 | C24: bord | F24: 21.5 | G24: 110 x 21,5 | J24: 6.08 | M24: stuks | N24: 110 | O24: ==B24*(N24*F24/10000)*J24
A25: 676521e85ff93f7b6d3f91fa | B25: 1 | C25: bord | F25: 25 | G25: 105 x 25 | J25: 6.08 | M25: stuks | N25: 105 | O25: ==B25*(N25*F25/10000)*J25
A26: 676521e85ff93f7b6d3f91fb | B26: 1 | C26: bord | F26: 25 | G26: 120 x 25 | J26: 6.08 | M26: stuks | N26: 120 | O26: ==B26*(N26*F26/10000)*J26
A27: 676521e85ff93f7b6d3f91fc | B27: 1 | C27: bord | F27: 131 | G27: 24 x 131 | J27: 6.08 | M27: stuks | N27: 24 | O27: ==B27*(N27*F27/10000)*J27
A28: 676521e85ff93f7b6d3f91fd | B28: 1 | C28: bord | F28: 30 | G28: 49 x 30 | J28: 6.08 | M28: stuks | N28: 49 | O28: ==B28*(N28*F28/10000)*J28
A29: 676521e85ff93f7b6d3f91fe | B29: 1 | C29: bord | F29: 79 | G29: 29 x 79 | J29: 6.08 | M29: stuks | N29: 29 | O29: ==B29*(N29*F29/10000)*J29
A30: 676521e85ff93f7b6d3f91ff | B30: 1 | C30: bord | F30: 14.5 | G30: 80 x 14,5 | J30: 6.08 | M30: stuks | N30: 80 | O30: ==B30*(N30*F30/10000)*J30
A31: 676521e85ff93f7b6d3f9200 | B31: 1 | C31: bord | F31: 38 | G31: 42 x 38 | J31: 6.08 | M31: stuks | N31: 42 | O31: ==B31*(N31*F31/10000)*J31
A32: 676521e85ff93f7b6d3f9201 | B32: 1 | C32: bord | F32: 19 | G32: 42 x 19 | J32: 6.08 | M32: stuks | N32: 42 | O32: ==B32*(N32*F32/10000)*J32
A33: 676521e85ff93f7b6d3f9202 | B33: 1 | C33: bord | F33: 19 | G33: 79 x 19 | J33: 6.08 | M33: stuks | N33: 79 | O33: ==B33*(N33*F33/10000)*J33
A34: 676521e85ff93f7b6d3f9203 | B34: 1 | C34: bord | F34: 52 | G34: 48 x 52 | J34: 6.08 | M34: stuks | N34: 48 | O34: ==B34*(N34*F34/10000)*J34
A35: 676521e85ff93f7b6d3f9204 | B35: 1 | C35: bord | F35: 33 | G35: 37 X 33 | J35: 6.08 | K35: 3 | M35: stuks | N35: 37 | O35: ==B35*(N35*F35/10000)*J35
A36: 676521e85ff93f7b6d3f9205 | B36: 1 | C36: bord | F36: 35 | G36: 46,5 X 35 | J36: 6.08 | K36: 3 | M36: stuks | N36: 46.5 | O36: ==B36*(N36*F36/10000)*J36
A37: 676521e85ff93f7b6d3f9206 | B37: 1 | C37: bord | F37: 67 | G37: 85 X 67 | J37: 6.08 | K37: 3 | M37: stuks | N37: 85 | O37: ==B37*(N37*F37/10000)*J37
A38: 676521e95ff93f7b6d3f9207 | B38: 1 | C38: bord | F38: 47 | G38: 12,5 x 47 | J38: 6.08 | K38: 3 | M38: stuks | N38: 12.5 | O38: ==B38*(N38*F38/10000)*J38
A39: 676521e95ff93f7b6d3f9208 | B39: 1 | C39: bord | F39: 114.3 | G39: 12 x 114,3 | J39: 6.08 | K39: 3 | M39: stuks | N39: 12 | O39: ==B39*(N39*F39/10000)*J39
A40: 676521e95ff93f7b6d3f9209 | B40: 1 | C40: bord | F40: 183 | G40: 40 x 183 | J40: 6.08 | K40: 3 | M40: stuks | N40: 40 | O40: ==B40*(N40*F40/10000)*J40
...

Sheet zwart
A1: _id | B1: available | C1: calculation_type | D1: depth_cm | E1: format | F1: height_cm | G1: name | H1: price_per_meter | I1: price_per_piece | J1: price_per_square_meter | K1: thickness | L1: total_meter_per_rol | M1: unit | N1: width_cm | O1: subtotal
A2: 676521dc5ff93f7b6d3f9169 | B2: 1 | C2: bord | F2: 19.5 | G2: 100,5 X 19,5 | J2: 6.08 | K2: 3 | M2: stuks | N2: 100.5 | O2: ==B2*(N2*F2/10000)*J2
A3: 676521dc5ff93f7b6d3f916a | B3: 1 | C3: bord | F3: 10 | G3: 103 X 10 | J3: 6.08 | K3: 3 | M3: stuks | N3: 103 | O3: ==B3*(N3*F3/10000)*J3
A4: 676521dc5ff93f7b6d3f916b | B4: 1 | C4: bord | F4: 27 | G4: 103 X 27 | J4: 6.08 | M4: stuks | N4: 103 | O4: ==B4*(N4*F4/10000)*J4
A5: 676521dc5ff93f7b6d3f916c | B5: 1 | C5: bord | F5: 67 | G5: 115 X 67 | J5: 6.08 | M5: stuks | N5: 115 | O5: ==B5*(N5*F5/10000)*J5
A6: 676521dd5ff93f7b6d3f916d | B6: 1 | C6: bord | F6: 78 | G6: 13 X 78 | J6: 6.08 | M6: stuks | N6: 13 | O6: ==B6*(N6*F6/10000)*J6
A7: 676521dd5ff93f7b6d3f916e | B7: 1 | C7: bord | F7: 90 | G7: 13 X 90 | J7: 6.08 | M7: stuks | N7: 13 | O7: ==B7*(N7*F7/10000)*J7
A8: 676521dd5ff93f7b6d3f916f | B8: 1 | C8: bord | F8: 19 | G8: 140 X 19 | J8: 6.08 | M8: stuks | N8: 140 | O8: ==B8*(N8*F8/10000)*J8
A9: 676521dd5ff93f7b6d3f9170 | B9: 1 | C9: bord | F9: 15 | G9: 150 X 15 | J9: 6.08 | M9: stuks | N9: 150 | O9: ==B9*(N9*F9/10000)*J9
A10: 676521dd5ff93f7b6d3f9171 | B10: 1 | C10: bord | F10: 63 | G10: 16 X 63 | J10: 6.08 | M10: stuks | N10: 16 | O10: ==B10*(N10*F10/10000)*J10
A11: 676521dd5ff93f7b6d3f9172 | B11: 73 | C11: bord | F11: 10 | G11: 20 X 10 | J11: 6.08 | M11: stuks | N11: 20 | O11: ==B11*(N11*F11/10000)*J11
A12: 676521dd5ff93f7b6d3f9173 | B12: 42 | C12: bord | F12: 15 | G12: 21 X 15 | J12: 6.08 | M12: stuks | N12: 21 | O12: ==B12*(N12*F12/10000)*J12
A13: 676521dd5ff93f7b6d3f9174 | B13: 1 | C13: bord | F13: 31 | G13: 22 X 31 | J13: 6.08 | M13: stuks | N13: 22 | O13: ==B13*(N13*F13/10000)*J13
A14: 676521dd5ff93f7b6d3f9175 | B14: 1 | C14: bord | F14: 50 | G14: 23,5 X 50 | J14: 6.08 | M14: stuks | N14: 23.5 | O14: ==B14*(N14*F14/10000)*J14
A15: 676521dd5ff93f7b6d3f9176 | B15: 1 | C15: bord | F15: 18 | G15: 245 X 18 | J15: 6.08 | M15: stuks | N15: 245 | O15: ==B15*(N15*F15/10000)*J15
... A60: 676521e15ff93f7b6d3f91a3 | B60: 1 | C60: bord | F60: 17.5 | G60: 120 x 17,5 | J60: 6.08 | M60: stuks | N60: 120 | O60: ==B60*(N60*F60/10000)*J60
A61: 676521e15ff93f7b6d3f91a4 | B61: 1 | C61: bord | F61: 12 | G61: 100 x 12 | J61: 6.08 | K61: 3 | M61: stuks | N61: 100 | O61: ==B61*(N61*F61/10000)*J61
A62: 676521e15ff93f7b6d3f91a5 | B62: 1 | C62: bord | F62: 19 | G62: 150 x 19 | J62: 6.08 | M62: stuks | N62: 150 | O62: ==B62*(N62*F62/10000)*J62
A63: 676521e15ff93f7b6d3f91a6 | B63: 1 | C63: bord | F63: 31 | G63: 77 x 31 | J63: 6.08 | M63: stuks | N63: 77 | O63: ==B63*(N63*F63/10000)*J63
A64: 676521e15ff93f7b6d3f91a7 | B64: 1 | C64: bord | F64: 70 | G64: 83 X 70 | J64: 6.08 | M64: stuks | N64: 83 | O64: ==B64*(N64*F64/10000)*J64
A65: 676521e15ff93f7b6d3f91a8 | B65: 1 | C65: bord | F65: 25.5 | G65: 240 X 25,5 | J65: 6.08 | K65: 3 | M65: stuks | N65: 240 | O65: ==B65*(N65*F65/10000)*J65
A66: 676521e15ff93f7b6d3f91a9 | B66: 0 | C66: bord | F66: 25 | G66: 70X25 | J66: 6.08 | K66: 3 | N66: 70 | O66: ==B66*(N66*F66/10000)*J66
A67: 676521e15ff93f7b6d3f91aa | B67: 0 | C67: bord | F67: 55 | G67: 135X55 | J67: 6.08 | K67: 3 | N67: 135 | O67: ==B67*(N67*F67/10000)*J67
A68: 676521e15ff93f7b6d3f91ab | B68: 0 | C68: bord | F68: 25 | G68: 145x25 | J68: 6.08 | K68: 3 | N68: 145 | O68: ==B68*(N68*F68/10000)*J68
A69: 676521e15ff93f7b6d3f91ac | B69: 2 | C69: bord | F69: 30 | G69: 40x30 | J69: 6.08 | M69: stuks | N69: 40 | O69: ==B69*(N69*F69/10000)*J69
A70: 676521e15ff93f7b6d3f91ad | B70: 1 | C70: bord | F70: 32 | G70: 40x32 | J70: 6.08 | M70: stuks | N70: 40 | O70: ==B70*(N70*F70/10000)*J70
A71: 676521e15ff93f7b6d3f91ae | B71: 1 | C71: bord | F71: 34 | G71: 40x34 | J71: 6.08 | M71: stuks | N71: 40 | O71: ==B71*(N71*F71/10000)*J71
A72: 676521e25ff93f7b6d3f91af | B72: 1 | C72: bord | F72: 38 | G72: 39 x 38 | J72: 6.08 | K72: 3 | M72: stuks | N72: 39 | O72: ==B72*(N72*F72/10000)*J72
N73: Total | O73: ==SUM(O2:O72)

Sheet wit
A1: _id | B1: available | C1: calculation_type | D1: depth_cm | E1: format | F1: height_cm | G1: name | H1: price_per_meter | I1: price_per_piece | J1: price_per_square_meter | K1: thickness | L1: total_meter_per_rol | M1: unit | N1: width_cm | O1: subtotal
A2: 676521ea5ff93f7b6d3f921d | B2: 1 | C2: bord | F2: 30 | G2: 41 x 30 | J2: 4.58 | K2: 3 | M2: stuks | N2: 41 | O2: ==B2*(N2*F2/10000)*J2
A3: 676521ea5ff93f7b6d3f921e | B3: 1 | C3: bord | F3: 20 | G3: 28 x 20 | J3: 4.58 | K3: 3 | M3: stuks | N3: 28 | O3: ==B3*(N3*F3/10000)*J3
A4: 676521ea5ff93f7b6d3f921f | B4: 1 | C4: bord | F4: 29 | G4: 20 x 29 | J4: 4.58 | K4: 3 | M4: stuks | N4: 20 | O4: ==B4*(N4*F4/10000)*J4
A5: 676521ea5ff93f7b6d3f9220 | B5: 1 | C5: bord | F5: 28 | G5: 24,5 x 28 | J5: 4.58 | K5: 3 | M5: stuks | N5: 24.5 | O5: ==B5*(N5*F5/10000)*J5
A6: 676521eb5ff93f7b6d3f9221 | B6: 2 | C6: bord | F6: 28.5 | G6: 25,5 x 28,5 | J6: 4.58 | K6: 3 | M6: stuks | N6: 25.5 | O6: ==B6*(N6*F6/10000)*J6
A7: 676521eb5ff93f7b6d3f9222 | B7: 1 | C7: bord | F7: 24 | G7: 60 x 24 | J7: 4.58 | K7: 3 | M7: stuks | N7: 60 | O7: ==B7*(N7*F7/10000)*J7
A8: 676521eb5ff93f7b6d3f9223 | B8: 1 | C8: bord | F8: 52 | G8: 20 x 52 | J8: 4.58 | K8: 3 | M8: stuks | N8: 20 | O8: ==B8*(N8*F8/10000)*J8
A9: 676521eb5ff93f7b6d3f9224 | B9: 1 | C9: bord | F9: 30 | G9: 40 x 30 | J9: 4.58 | K9: 3 | M9: stuks | N9: 40 | O9: ==B9*(N9*F9/10000)*J9
A10: 676521eb5ff93f7b6d3f9225 | B10: 1 | C10: bord | F10: 25 | G10: 28 x 25 | J10: 4.58 | K10: 3 | M10: stuks | N10: 28 | O10: ==B10*(N10*F10/10000)*J10
A11: 676521eb5ff93f7b6d3f9226 | B11: 2 | C11: bord | F11: 15 | G11: 22 x 15 | J11: 4.58 | K11: 3 | M11: stuks | N11: 22 | O11: ==B11*(N11*F11/10000)*J11
A12: 676521eb5ff93f7b6d3f9227 | B12: 1 | C12: bord | F12: 19 | G12: 20 x 19 | J12: 4.58 | K12: 3 | M12: stuks | N12: 20 | O12: ==B12*(N12*F12/10000)*J12
A13: 676521eb5ff93f7b6d3f9228 | B13: 1 | C13: bord | F13: 20 | G13: 23 x 20 | J13: 4.58 | K13: 3 | M13: stuks | N13: 23 | O13: ==B13*(N13*F13/10000)*J13
... A94: 676521f35ff93f7b6d3f9279 | B94: 1 | C94: bord | F94: 115 | G94: 200x115 | J94: 4.58 | K94: 3 | M94: stuks | N94: 200 | O94: ==B94*(N94*F94/10000)*J94
N95: Total | O95: ==SUM(O2:O94)

Sheet kanaalplaten
A1: _id | B1: available | C1: calculation_type | D1: depth_cm | E1: format | F1: height_cm | G1: name | H1: price_per_meter | I1: price_per_piece | J1: price_per_square_meter | K1: thickness | L1: total_meter_per_rol | M1: unit | N1: width_cm | O1: subtotal
A2: 676521e45ff93f7b6d3f91d3 | B2: 1 | C2: bord | F2: 200 | G2: 60 X 200 | J2: 12.5 | M2: stuks | N2: 60 | O2: ==B2*(N2*F2/10000)*J2
A3: 676521e45ff93f7b6d3f91d4 | B3: 1 | C3: bord | F3: 30.5 | G3: 200 X 30,5 | J3: 12.5 | M3: stuks | N3: 200 | O3: ==B3*(N3*F3/10000)*J3
A4: 676521e45ff93f7b6d3f91d5 | B4: 1 | C4: bord | F4: 45 | G4: 65 X 45 | J4: 12.5 | M4: stuks | N4: 65 | O4: ==B4*(N4*F4/10000)*J4
A5: 676521e55ff93f7b6d3f91d6 | B5: 6 | C5: bord | F5: 45 | G5: 125 X 45 | J5: 12.5 | M5: stuks | N5: 125 | O5: ==B5*(N5*F5/10000)*J5
A6: 676521e55ff93f7b6d3f91d7 | B6: 0 | C6: bord | F6: 250 | G6: 100 x 250 | J6: 12.5 | K6: 8 | M6: stuks | N6: 100 | O6: ==B6*(N6*F6/10000)*J6
A7: 676521e55ff93f7b6d3f91d8 | B7: 2 | C7: bord | F7: 50 | G7: 70 x 50 | J7: 12.5 | K7: 3 | M7: stuks | N7: 70 | O7: ==B7*(N7*F7/10000)*J7
N8: Total | O8: ==SUM(O2:O7)

Sheet brushed_steel
A1: _id | B1: available | C1: calculation_type | D1: depth_cm | E1: format | F1: height_cm | G1: name | H1: price_per_meter | I1: price_per_piece | J1: price_per_square_meter | K1: thickness | L1: total_meter_per_rol | M1: unit | N1: width_cm | O1: subtotal
A2: 676521f35ff93f7b6d3f927a | B2: 1 | C2: bord | F2: 87 | G2: 150x87 | J2: 1.31 | K2: 3 | M2: stuks | N2: 150 | O2: ==B2*(N2*F2/10000)*J2
A3: 676521f35ff93f7b6d3f927b | B3: 1 | C3: bord | F3: 35 | G3: 215x35 | J3: 0.75 | K3: 3 | M3: stuks | N3: 215 | O3: ==B3*(N3*F3/10000)*J3
A4: 676521f35ff93f7b6d3f927c | B4: 1 | C4: bord | F4: 35 | G4: 175 x 35 | J4: 0.61 | K4: 3 | M4: stuks | N4: 175 | O4: ==B4*(N4*F4/10000)*J4
N5: Total | O5: ==SUM(O2:O4)

Sheet plexiglas
A1: _id | B1: available | C1: calculation_type | D1: depth_cm | E1: format | F1: height_cm | G1: name | H1: price_per_meter | I1: price_per_piece | J1: price_per_square_meter | K1: thickness | L1: total_meter_per_rol | M1: unit | N1: width_cm | O1: subtotal
A2: 676521e55ff93f7b6d3f91de | B2: 7 | C2: bord | F2: 30 | G2: 30 x 30 | J2: 151.46 | K2: 7 | M2: stuks | N2: 30 | O2: ==B2*(N2*F2/10000)*J2
A3: 676521e55ff93f7b6d3f91df | B3: 7 | C3: bord | F3: 25 | G3: 30 x 25 | J3: 151.46 | K3: 7 | M3: stuks | N3: 30 | O3: ==B3*(N3*F3/10000)*J3
A4: 676521e65ff93f7b6d3f91e0 | B4: 1 | C4: bord | F4: 42 | G4: A3 | J4: 151.46 | K4: 7 | M4: stuks | N4: 29.7 | O4: ==B4*(N4*F4/10000)*J4
A5: 676521e65ff93f7b6d3f91e1 | B5: 3 | C5: bord | F5: 10 | G5: 30 x 10 | J5: 151.46 | K5: 7 | M5: stuks | N5: 30 | O5: ==B5*(N5*F5/10000)*J5
A6: 676521e65ff93f7b6d3f91e2 | B6: 1 | C6: bord | F6: 50 | G6: 70 x 50 | J6: 151.46 | K6: 5 | M6: stuks | N6: 70 | O6: ==B6*(N6*F6/10000)*J6
N7: Total | O7: ==SUM(O2:O6)

Sheet total
A1: Sheet Name | B1: Subtotal
A2: afstandshouder | B2: ==afstandshouder!O6
A3: hout | B3: ==hout!O6
A4: plexi_opaal | B4: ==plexi_opaal!O3
A5: forex_zwart | B5: ==forex_zwart!O37
A6: forex_wit | B6: ==forex_wit!O56
A7: zwart | B7: ==zwart!O73
A8: wit | B8: ==wit!O95
A9: kanaalplaten | B9: ==kanaalplaten!O8
A10: brushed_steel | B10: ==brushed_steel!O5
A11: plexiglas | B11: ==plexiglas!O7
A12: Grand Total | B12: ==SUM(B2:B11)
