Workbook

Sheet borden_afstandshouder
A1: _id | B1: available | C1: calculation_type | D1: depth_cm | E1: format | F1: height_cm | G1: name | H1: price_per_meter | I1: price_per_piece | J1: price_per_square_meter | K1: thickness | L1: total_meter_per_rol | M1: unit | N1: width_cm | O1: subtotal
A2: 676521ea5ff93f7b6d3f9219 | B2: 18 | C2: stuk | G2: Zwart draai | I2: 5.68 | K2: 1.5 | M2: stuks | O2: ==B2*I2
A3: 676521ea5ff93f7b6d3f921a | B3: 108 | C3: stuk | G3: Klein | I3: 0.57 | M3: stuks | O3: ==B3*I3
A4: 676521ea5ff93f7b6d3f921b | B4: 123 | C4: stuk | G4: Middel | I4: 0.58 | K4: 0 | M4: stuks | O4: ==B4*I4
A5: 676521ea5ff93f7b6d3f921c | B5: 97 | C5: stuk | G5: Groot | I5: 0.61 | M5: stuks | O5: ==B5*I5
N6: Total | O6: ==SUM(O2:O5)

Sheet borden_hout
A1: _id | B1: available | C1: calculation_type | D1: depth_cm | E1: format | F1: height_cm | G1: name | H1: price_per_meter | I1: price_per_piece | J1: price_per_square_meter | K1: thickness | L1: total_meter_per_rol | M1: unit | N1: width_cm | O1: subtotal
A2: 676521e55ff93f7b6d3f91d9 | B2: 3 | C2: bord | D2: 2 | F2: 7.5 | G2: 410 X 7,5 X 2 | M2: stuks | N2: 410 | O2: ==B2*(N2*F2/10000)*J2
A3: 676521e55ff93f7b6d3f91da | B3: 1 | C3: bord | D3: 6 | F3: 6.5 | G3: 212 X 6,5 X 6 | M3: stuks | N3: 212 | O3: ==B3*(N3*F3/10000)*J3
A4: 676521e55ff93f7b6d3f91db | B4: 1 | C4: bord | D4: 5.5 | F4: 8 | G4: 3 X 8 X 5,5 | M4: stuks | N4: 3 | O4: ==B4*(N4*F4/10000)*J4
A5: 676521e55ff93f7b6d3f91dc | B5: 2 | C5: bord | D5: 8.5 | F5: 9 | G5: 180 X 9 X 8,5 | M5: stuks | N5: 180 | O5: ==B5*(N5*F5/10000)*J5
N6: Total | O6: ==SUM(O2:O5)

Sheet borden_plexi_opaal
A1: _id | B1: available | C1: calculation_type | D1: depth_cm | E1: format | F1: height_cm | G1: name | H1: price_per_meter | I1: price_per_piece | J1: price_per_square_meter | K1: thickness | L1: total_meter_per_rol | M1: unit | N1: width_cm | O1: subtotal
A2: 676521e55ff93f7b6d3f91dd | B2: 1 | C2: bord | F2: 100 | G2: 180 X 100 | J2: 6.19 | K2: 3 | M2: stuks | N2: 180 | O2: ==B2*(N2*F2/10000)*J2
N3: Total | O3: ==SUM(O2:O2)

Sheet borden_forex_zwart
A1: _id | B1: available | C1: calculation_type | D1: depth_cm | E1: format | F1: height_cm | G1: name | H1: price | I1: price_per_meter | J1: price_per_piece | K1: price_per_square_meter | L1: thickness | M1: total_meter_per_rol | N1: unit | O1: width_cm | P1: subtotal
A2: 676521e25ff93f7b6d3f91b0 | B2: 2 | C2: bord | F2: 100 | G2: 120x100 | K2: 4.76 | L2: 1 | N2: stuks | O2: 120 | P2: ==B2*(O2*F2/10000)*K2
A3: 676521e25ff93f7b6d3f91b1 | B3: 1 | C3: bord | F3: 118 | G3: 122x118 | K3: 4.76 | L3: 4 | N3: stuks | O3: 122 | P3: ==B3*(O3*F3/10000)*K3
A4: 676521e25ff93f7b6d3f91b2 | B4: 1 | C4: bord | F4: 40 | G4: 30 x 40 | K4: 4.76 | N4: stuks | O4: 30 | P4: ==B4*(O4*F4/10000)*K4
A5: 676521e25ff93f7b6d3f91b3 | B5: 1 | C5: bord | F5: 147 | G5: 150x147 | K5: 4.76 | L5: 4 | N5: stuks | O5: 150 | P5: ==B5*(O5*F5/10000)*K5
A6: 676521e25ff93f7b6d3f91b4 | B6: 1 | C6: bord | F6: 42 | G6: 32x24 | K6: 4.76 | L6: 3 | N6: stuks | O6: 44 | P6: ==B6*(O6*F6/10000)*K6
A7: 676521e25ff93f7b6d3f91b5 | B7: 2 | C7: bord | F7: 18 | G7: 200x18 | K7: 4.76 | L7: 1 | N7: stuks | O7: 200 | P7: ==B7*(O7*F7/10000)*K7
A8: 676521e25ff93f7b6d3f91b6 | B8: 1 | C8: bord | F8: 120 | G8: 204x120 ZW | K8: 4.76 | L8: 4 | N8: stuks | O8: 204 | P8: ==B8*(O8*F8/10000)*K8
A9: 676521e25ff93f7b6d3f91b7 | B9: 1 | C9: bord | F9: 9.5 | G9: 23x9,5 | K9: 4.76 | L9: 4 | N9: stuks | O9: 23 | P9: ==B9*(O9*F9/10000)*K9
A10: 676521e25ff93f7b6d3f91b8 | B10: 1 | C10: bord | F10: 18 | G10: 24 x 18 | K10: 4.76 | L10: 5 | N10: stuks | O10: 24 | P10: ==B10*(O10*F10/10000)*K10
A11: 676521e25ff93f7b6d3f91b9 | B11: 1 | C11: bord | F11: 97 | G11: 24x97 ZW | K11: 4.76 | L11: 5 | N11: stuks | O11: 24 | P11: ==B11*(O11*F11/10000)*K11
A12: 676521e25ff93f7b6d3f91ba | B12: 3 | C12: bord | F12: 30 | G12: 30x30 | K12: 4.76 | L12: 7 | N12: stuks | O12: 30 | P12: ==B12*(O12*F12/10000)*K12
A13: 676521e25ff93f7b6d3f91bb | B13: 8 | C13: bord | F13: 29 | G13: 32x29 | K13: 4.76 | L13: 4 | N13: stuks | O13: 32 | P13: ==B13*(O13*F13/10000)*K13
A14: 676521e35ff93f7b6d3f91bc | B14: 1 | C14: bord | F14: 29 | G14: 34x29 | K14: 4.76 | L14: 5 | N14: stuks | O14: 34 | P14: ==B14*(O14*F14/10000)*K14
A15: 676521e35ff93f7b6d3f91bd | B15: 1 | C15: bord | F15: 18 | G15: 40 x 18 | K15: 4.76 | L15: 5 | N15: stuks | O15: 40 | P15: ==B15*(O15*F15/10000)*K15
A16: 676521e35ff93f7b6d3f91be | B16: 1 | C16: bord | F16: 40 | G16: 40 x 40 | K16: 4.76 | L16: 5 | N16: stuks | O16: 40 | P16: ==B16*(O16*F16/10000)*K16
A17: 676521e35ff93f7b6d3f91c1 | B17: 1 | C17: bord | F17: 40 | G17: 100 x 40 | K17: 4.76 | N17: stuks | O17: 100 | P17: ==B17*(O17*F17/10000)*K17
A18: 676521e35ff93f7b6d3f91c2 | B18: 1 | C18: bord | F18: 11 | G18: 53 x 11 | K18: 4.76 | N18: stuks | O18: 53 | P18: ==B18*(O18*F18/10000)*K18
A19: 676521e35ff93f7b6d3f91c3 | B19: 1 | C19: bord | F19: 24 | G19: 97 x 24 | K19: 4.76 | L19: 0 | N19: stuks | O19: 97 | P19: ==B19*(O19*F19/10000)*K19
A20: 676521e35ff93f7b6d3f91c4 | B20: 1 | C20: bord | F20: 18 | G20: 50 x 18 | K20: 4.76 | L20: 5 | N20: stuks | O20: 50 | P20: ==B20*(O20*F20/10000)*K20
A21: 676521e35ff93f7b6d3f91c5 | B21: 1 | C21: bord | F21: 50 | G21: 50 x 50 | K21: 4.76 | L21: 2 | N21: stuks | O21: 50 | P21: ==B21*(O21*F21/10000)*K21
A22: 676521e35ff93f7b6d3f91c6 | B22: 1 | C22: bord | F22: 20 | G22: 50x20 | K22: 4.76 | L22: 5 | N22: stuks | O22: 50 | P22: ==B22*(O22*F22/10000)*K22
A23: 676521e35ff93f7b6d3f91c7 | B23: 1 | C23: bord | F23: 123 | G23: 305 x 123 | K23: 4.76 | N23: stuks | O23: 305 | P23: ==B23*(O23*F23/10000)*K23
A24: 676521e35ff93f7b6d3f91c8 | B24: 1 | C24: bord | F24: 100 | G24: 27 x 100 | K24: 4.76 | N24: stuks | O24: 27 | P24: ==B24*(O24*F24/10000)*K24
A25: 676521e45ff93f7b6d3f91c9 | B25: 1 | C25: bord | F25: 22 | G25: 59x22 | K25: 4.76 | L25: 5 | N25: stuks | O25: 59 | P25: ==B25*(O25*F25/10000)*K25
A26: 676521e45ff93f7b6d3f91ca | B26: 3 | C26: bord | F26: 17.5 | G26: 60 x 17,5 | K26: 4.76 | L26: 5 | N26: stuks | O26: 60 | P26: ==B26*(O26*F26/10000)*K26
A27: 676521e45ff93f7b6d3f91cb | B27: 2 | C27: bord | F27: 38 | G27: 60x38 | K27: 4.76 | L27: 8 | N27: stuks | O27: 60 | P27: ==B27*(O27*F27/10000)*K27
A28: 676521e45ff93f7b6d3f91cc | B28: 2 | C28: bord | F28: 60 | G28: 60x60 ZW | K28: 4.76 | L28: 2 | N28: stuks | O28: 60 | P28: ==B28*(O28*F28/10000)*K28
A29: 676521e45ff93f7b6d3f91cd | B29: 1 | C29: bord | F29: 108.5 | G29: 22,5 X 108,5 | K29: 4.76 | N29: stuks | O29: 22.5 | P29: ==B29*(O29*F29/10000)*K29
A30: 676521e45ff93f7b6d3f91ce | B30: 1 | C30: bord | F30: 51 | G30: 80 X 51 | K30: 4.76 | L30: 0 | N30: stuks | O30: 80 | P30: ==B30*(O30*F30/10000)*K30
A31: 676521e45ff93f7b6d3f91cf | B31: 1 | C31: bord | F31: 37 | G31: 48,5 x 37 | K31: 4.76 | L31: 5 | N31: stuks | O31: 48.5 | P31: ==B31*(O31*F31/10000)*K31
A32: 676521e45ff93f7b6d3f91d1 | B32: 2 | C32: bord | F32: 35 | G32: 72 x 35 | K32: 4.76 | L32: 3 | N32: stuks | O32: 72 | P32: ==B32*(O32*F32/10000)*K32
A33: 676521e45ff93f7b6d3f91d2 | B33: 1 | C33: bord | F33: 24 | G33: 64 X 24@ | K33: 4.76 | L33: 3 | N33: stuks | O33: 64 | P33: ==B33*(O33*F33/10000)*K33
A34: 678135c22e2cbf8223441cb3 | B34: 1 | D34: 0 | F34: 0 | G34: 34X24 | I34: 0 | J34: 0 | K34: 0 | L34: 3 | M34: 0 | N34: stuks | O34: 0 | P34: ==0
A35: 678135fc2e2cbf8223441cb5 | B35: 1 | D35: 0 | F35: 0 | G35: 38X35 | I35: 0 | J35: 0 | K35: 0 | L35: 5 | M35: 0 | N35: stuks | O35: 0 | P35: ==0
A36: 67b499d7e3058867d1720a48 | B36: 1 | D36: 0 | F36: 0 | G36: 106 x 33 | I36: 0 | J36: 0 | K36: 0 | L36: 3 | M36: 0 | O36: 0 | P36: ==0
A37: 67b499ebe3058867d1720a49 | B37: 1 | D37: 0 | F37: 0 | G37: 124 x 19 | I37: 0 | J37: 0 | K37: 0 | L37: 3 | M37: 0 | O37: 0 | P37: ==0
A38: 67b499ffe3058867d1720a4a | B38: 1 | D38: 0 | F38: 0 | G38: 156 x 52 | I38: 0 | J38: 0 | K38: 0 | L38: 3 | M38: 0 | O38: 0 | P38: ==0
A39: 67b49a33e3058867d1720a4c | B39: 1 | D39: 0 | F39: 0 | G39: 19 x 52 | I39: 0 | J39: 0 | K39: 0 | L39: 3 | M39: 0 | O39: 0 | P39: ==0
A40: 67b49a5ee3058867d1720a4e | B40: 1 | D40: 0 | F40: 0 | G40: 68 x 37 | I40: 0 | J40: 0 | K40: 0 | L40: 3 | M40: 0 | O40: 0 | P40: ==0
...

Sheet borden_forex_wit
A1: _id | B1: available | C1: calculation_type | D1: depth_cm | E1: format | F1: height_cm | G1: name | H1: price_per_meter | I1: price_per_piece | J1: price_per_square_meter | K1: thickness | L1: total_meter_per_rol | M1: unit | N1: width_cm | O1: subtotal
A2: 676521e65ff93f7b6d3f91e3 | B2: 1 | C2: bord | F2: 20 | G2: 50 X 20 | J2: 6.08 | M2: stuks | N2: 50 | O2: ==B2*(N2*F2/10000)*J2
A3: 676521e65ff93f7b6d3f91e4 | B3: 1 | C3: bord | F3: 20 | G3: 122,5 X 20 | J3: 6.08 | M3: stuks | N3: 122.5 | O3: ==B3*(N3*F3/10000)*J3
A4: 676521e65ff93f7b6d3f91e5 | B4: 1 | C4: bord | F4: 29 | G4: 34 X 29 | J4: 6.08 | M4: stuks | N4: 34 | O4: ==B4*(N4*F4/10000)*J4
A5: 676521e65ff93f7b6d3f91e6 | B5: 1 | C5: bord | F5: 29 | G5: 32 X 29 | J5: 6.08 | M5: stuks | N5: 32 | O5: ==B5*(N5*F5/10000)*J5
A6: 676521e65ff93f7b6d3f91e7 | B6: 2 | C6: bord | F6: 29 | G6: 42 x 29 | J6: 6.08 | M6: stuks | N6: 42 | O6: ==B6*(N6*F6/10000)*J6
A7: 676521e65ff93f7b6d3f91e9 | B7: 2 | C7: bord | F7: 22 | G7: 59 x 22 | J7: 6.08 | M7: stuks | N7: 59 | O7: ==B7*(N7*F7/10000)*J7
A8: 676521e65ff93f7b6d3f91ea | B8: 1 | C8: bord | F8: 20 | G8: 50 x 20 | J8: 6.08 | M8: stuks | N8: 50 | O8: ==B8*(N8*F8/10000)*J8
A9: 676521e75ff93f7b6d3f91ec | B9: 2 | C9: bord | F9: 35 | G9: 45 x 35 | J9: 6.08 | K9: 1 | M9: stuks | N9: 45 | O9: ==B9*(N9*F9/10000)*J9
A10: 676521e75ff93f7b6d3f91ed | B10: 1 | C10: bord | F10: 50 | G10: 22,5 x 50 | J10: 6.08 | K10: 1 | M10: stuks | N10: 22.5 | O10: ==B10*(N10*F10/10000)*J10
A11: 676521e75ff93f7b6d3f91ee | B11: 1 | C11: bord | F11: 17.5 | G11: 60 x 17,5 | J11: 6.08 | M11: stuks | N11: 60 | O11: ==B11*(N11*F11/10000)*J11
A12: 676521e75ff93f7b6d3f91ef | B12: 4 | C12: bord | F12: 9.5 | G12: 24 x 9,5 | J12: 6.08 | M12: stuks | N12: 24 | O12: ==B12*(N12*F12/10000)*J12
A13: 676521e75ff93f7b6d3f91f0 | B13: 3 | C13: bord | F13: 15 | G13: 20 x 15 | J13: 6.08 | M13: stuks | N13: 20 | O13: ==B13*(N13*F13/10000)*J13
A14: 676521e75ff93f7b6d3f91f1 | B14: 3 | C14: bord | F14: 18 | G14: 20 x 18 | J14: 6.08 | M14: stuks | N14: 20 | O14: ==B14*(N14*F14/10000)*J14
A15: 676521e75ff93f7b6d3f91f2 | B15: 7 | C15: bord | F15: 18 | G15: 24 x 18 | J15: 6.08 | M15: stuks | N15: 24 | O15: ==B15*(N15*F15/10000)*J15
A16: 676521e75ff93f7b6d3f91f3 | B16: 1 | C16: bord | F16: 22 | G16: 31 x 22 | J16: 6.08 | M16: stuks | N16: 31 | O16: ==B16*(N16*F16/10000)*J16
A17: 676521e75ff93f7b6d3f91f4 | B17: 3 | C17: bord | F17: 30 | G17: 30 x 30 | J17: 6.08 | M17: stuks | N17: 30 | O17: ==B17*(N17*F17/10000)*J17
A18: 676521e75ff93f7b6d3f91f5 | B18: 2 | C18: bord | F18: 50 | G18: 40 x 50 | J18: 6.08 | K18: 8 | M18: stuks | N18: 40 | O18: ==B18*(N18*F18/10000)*J18
A19: 676521e75ff93f7b6d3f91f6 | B19: 0 | C19: bord | F19: 50 | G19: 50 x 50 | J19: 6.08 | K19: 1 | M19: stuks | N19: 50 | O19: ==B19*(N19*F19/10000)*J19
A20: 676521e75ff93f7b6d3f91f7 | B20: 5 | C20: bord | F20: 35.5 | G20: 22,5 x 35,5 | J20: 6.08 | K20: 3 | M20: stuks | N20: 22.5 | O20: ==B20*(N20*F20/10000)*J20
A21: 676521e75ff93f7b6d3f91f8 | B21: 1 | C21: bord | F21: 58 | G21: 28 x 58 | J21: 6.08 | M21: stuks | N21: 28 | O21: ==B21*(N21*F21/10000)*J21
A22: 676521e75ff93f7b6d3f91f9 | B22: 1 | C22: bord | F22: 21.5 | G22: 110 x 21,5 | J22: 6.08 | M22: stuks | N22: 110 | O22: ==B22*(N22*F22/10000)*J22
A23: 676521e85ff93f7b6d3f91fa | B23: 1 | C23: bord | F23: 25 | G23: 105 x 25 | J23: 6.08 | M23: stuks | N23: 105 | O23: ==B23*(N23*F23/10000)*J23
A24: 676521e85ff93f7b6d3f91fb | B24: 1 | C24: bord | F24: 25 | G24: 120 x 25 | J24: 6.08 | M24: stuks | N24: 120 | O24: ==B24*(N24*F24/10000)*J24
A25: 676521e85ff93f7b6d3f91fc | B25: 1 | C25: bord | F25: 131 | G25: 24 x 131 | J25: 6.08 | M25: stuks | N25: 24 | O25: ==B25*(N25*F25/10000)*J25
A26: 676521e85ff93f7b6d3f91fd | B26: 1 | C26: bord | F26: 30 | G26: 49 x 30 | J26: 6.08 | M26: stuks | N26: 49 | O26: ==B26*(N26*F26/10000)*J26
A27: 676521e85ff93f7b6d3f91fe | B27: 1 | C27: bord | F27: 79 | G27: 29 x 79 | J27: 6.08 | M27: stuks | N27: 29 | O27: ==B27*(N27*F27/10000)*J27
A28: 676521e85ff93f7b6d3f91ff | B28: 1 | C28: bord | F28: 14.5 | G28: 80 x 14,5 | J28: 6.08 | M28: stuks | N28: 80 | O28: ==B28*(N28*F28/10000)*J28
A29: 676521e85ff93f7b6d3f9200 | B29: 1 | C29: bord | F29: 38 | G29: 42 x 38 | J29: 6.08 | M29: stuks | N29: 42 | O29: ==B29*(N29*F29/10000)*J29
A30: 676521e85ff93f7b6d3f9201 | B30: 1 | C30: bord | F30: 19 | G30: 42 x 19 | J30: 6.08 | M30: stuks | N30: 42 | O30: ==B30*(N30*F30/10000)*J30
A31: 676521e85ff93f7b6d3f9202 | B31: 1 | C31: bord | F31: 19 | G31: 79 x 19 | J31: 6.08 | M31: stuks | N31: 79 | O31: ==B31*(N31*F31/10000)*J31
A32: 676521e85ff93f7b6d3f9204 | B32: 1 | C32: bord | F32: 33 | G32: 37 X 33 | J32: 6.08 | K32: 3 | M32: stuks | N32: 37 | O32: ==B32*(N32*F32/10000)*J32
A33: 676521e85ff93f7b6d3f9205 | B33: 1 | C33: bord | F33: 35 | G33: 46,5 X 35 | J33: 6.08 | K33: 3 | M33: stuks | N33: 46.5 | O33: ==B33*(N33*F33/10000)*J33
A34: 676521e85ff93f7b6d3f9206 | B34: 1 | C34: bord | F34: 67 | G34: 85 X 67 | J34: 6.08 | K34: 3 | M34: stuks | N34: 85 | O34: ==B34*(N34*F34/10000)*J34
A35: 676521e95ff93f7b6d3f9209 | B35: 1 | C35: bord | F35: 183 | G35: 40 x 183 | J35: 6.08 | K35: 3 | M35: stuks | N35: 40 | O35: ==B35*(N35*F35/10000)*J35
A36: 676521e95ff93f7b6d3f920a | B36: 1 | C36: bord | F36: 143 | G36: 47,5 x 143 | J36: 6.08 | K36: 3 | M36: stuks | N36: 47.5 | O36: ==B36*(N36*F36/10000)*J36
A37: 676521e95ff93f7b6d3f920b | B37: 1 | C37: bord | F37: 27.5 | G37: 33x27,5 | J37: 6.08 | K37: 3 | M37: stuks | N37: 33 | O37: ==B37*(N37*F37/10000)*J37
A38: 676521e95ff93f7b6d3f920c | B38: 0 | C38: bord | F38: 47.5 | G38: 143x47,5 | J38: 6.08 | K38: 3 | M38: stuks | N38: 143 | O38: ==B38*(N38*F38/10000)*J38
A39: 676521e95ff93f7b6d3f920d | B39: 0 | C39: bord | F39: 29.5 | G39: 41x29,5 | J39: 6.08 | K39: 10 | M39: stuks | N39: 41 | O39: ==B39*(N39*F39/10000)*J39
A40: 676521e95ff93f7b6d3f920e | B40: 0 | C40: bord | F40: 49 | G40: 30x49 | J40: 6.08 | K40: 10 | M40: stuks | N40: 156 | O40: ==B40*(N40*F40/10000)*J40
...

Sheet borden_zwart
A1: _id | B1: available | C1: calculation_type | D1: depth_cm | E1: format | F1: height_cm | G1: name | H1: price_per_meter | I1: price_per_piece | J1: price_per_square_meter | K1: thickness | L1: total_meter_per_rol | M1: unit | N1: width_cm | O1: subtotal
A2: 676521dc5ff93f7b6d3f9169 | B2: 1 | C2: bord | F2: 19.5 | G2: 100,5 X 19,5 | J2: 6.08 | K2: 3 | M2: stuks | N2: 100.5 | O2: ==B2*(N2*F2/10000)*J2
A3: 676521dc5ff93f7b6d3f916a | B3: 1 | C3: bord | F3: 10 | G3: 103 X 10 | J3: 6.08 | K3: 3 | M3: stuks | N3: 103 | O3: ==B3*(N3*F3/10000)*J3
A4: 676521dc5ff93f7b6d3f916b | B4: 1 | C4: bord | F4: 27 | G4: 103 X 27 | J4: 6.08 | M4: stuks | N4: 103 | O4: ==B4*(N4*F4/10000)*J4
A5: 676521dc5ff93f7b6d3f916c | B5: 1 | C5: bord | F5: 67 | G5: 115 X 67 | J5: 6.08 | M5: stuks | N5: 115 | O5: ==B5*(N5*F5/10000)*J5
A6: 676521dd5ff93f7b6d3f916d | B6: 1 | C6: bord | F6: 78 | G6: 13 X 78 | J6: 6.08 | M6: stuks | N6: 13 | O6: ==B6*(N6*F6/10000)*J6
A7: 676521dd5ff93f7b6d3f916e | B7: 1 | C7: bord | F7: 90 | G7: 13 X 90 | J7: 6.08 | M7: stuks | N7: 13 | O7: ==B7*(N7*F7/10000)*J7
A8: 676521dd5ff93f7b6d3f916f | B8: 1 | C8: bord | F8: 19 | G8: 140 X 19 | J8: 6.08 | M8: stuks | N8: 140 | O8: ==B8*(N8*F8/10000)*J8
A9: 676521dd5ff93f7b6d3f9171 | B9: 1 | C9: bord | F9: 63 | G9: 16 X 63 | J9: 6.08 | M9: stuks | N9: 16 | O9: ==B9*(N9*F9/10000)*J9
A10: 676521dd5ff93f7b6d3f9172 | B10: 73 | C10: bord | F10: 10 | G10: 20 X 10 | J10: 6.08 | M10: stuks | N10: 20 | O10: ==B10*(N10*F10/10000)*J10
A11: 676521dd5ff93f7b6d3f9173 | B11: 42 | C11: bord | F11: 15 | G11: 21 X 15 | J11: 6.08 | M11: stuks | N11: 21 | O11: ==B11*(N11*F11/10000)*J11
A12: 676521dd5ff93f7b6d3f9174 | B12: 1 | C12: bord | F12: 31 | G12: 22 X 31 | J12: 6.08 | M12: stuks | N12: 22 | O12: ==B12*(N12*F12/10000)*J12
A13: 676521dd5ff93f7b6d3f9175 | B13: 1 | C13: bord | F13: 50 | G13: 23,5 X 50 | J13: 6.08 | M13: stuks | N13: 23.5 | O13: ==B13*(N13*F13/10000)*J13
A14: 676521dd5ff93f7b6d3f9176 | B14: 1 | C14: bord | F14: 18 | G14: 245 X 18 | J14: 6.08 | M14: stuks | N14: 245 | O14: ==B14*(N14*F14/10000)*J14
A15: 676521dd5ff93f7b6d3f9178 | B15: 1 | C15: bord | F15: 64 | G15: 25 X 64 | J15: 6.08 | M15: stuks | N15: 25 | O15: ==B15*(N15*F15/10000)*J15
... A55: 676521e15ff93f7b6d3f91a3 | B55: 1 | C55: bord | F55: 17.5 | G55: 120 x 17,5 | J55: 6.08 | M55: stuks | N55: 120 | O55: ==B55*(N55*F55/10000)*J55
A56: 676521e15ff93f7b6d3f91a4 | B56: 1 | C56: bord | F56: 12 | G56: 100 x 12 | J56: 6.08 | K56: 3 | M56: stuks | N56: 100 | O56: ==B56*(N56*F56/10000)*J56
A57: 676521e15ff93f7b6d3f91a6 | B57: 1 | C57: bord | F57: 31 | G57: 77 x 31 | J57: 6.08 | M57: stuks | N57: 77 | O57: ==B57*(N57*F57/10000)*J57
A58: 676521e15ff93f7b6d3f91a8 | B58: 1 | C58: bord | F58: 25.5 | G58: 240 X 25,5 | J58: 6.08 | K58: 3 | M58: stuks | N58: 240 | O58: ==B58*(N58*F58/10000)*J58
A59: 676521e15ff93f7b6d3f91aa | B59: 0 | C59: bord | F59: 55 | G59: 135X55 | J59: 6.08 | K59: 3 | N59: 135 | O59: ==B59*(N59*F59/10000)*J59
A60: 676521e15ff93f7b6d3f91ab | B60: 0 | C60: bord | F60: 25 | G60: 145x25 | J60: 6.08 | K60: 3 | N60: 145 | O60: ==B60*(N60*F60/10000)*J60
A61: 676521e15ff93f7b6d3f91ac | B61: 2 | C61: bord | F61: 30 | G61: 40x30 | J61: 6.08 | M61: stuks | N61: 40 | O61: ==B61*(N61*F61/10000)*J61
A62: 676521e15ff93f7b6d3f91ad | B62: 1 | C62: bord | F62: 32 | G62: 40x32 | J62: 6.08 | M62: stuks | N62: 40 | O62: ==B62*(N62*F62/10000)*J62
A63: 676521e15ff93f7b6d3f91ae | B63: 1 | C63: bord | F63: 34 | G63: 40x34 | J63: 6.08 | M63: stuks | N63: 40 | O63: ==B63*(N63*F63/10000)*J63
A64: 6780cdcbc236632b82276853 | B64: 1 | D64: 0 | F64: 0 | G64: 197x42,5 | H64: 0 | I64: 0 | J64: 0 | K64: 3 | L64: 0 | M64: stuks | N64: 0 | O64: ==0
A65: 67a0d783fce57378f3d031e5 | B65: 1 | D65: 0 | F65: 0 | G65: 205 x 162,5 | H65: 0 | I65: 0 | J65: 0 | K65: 3 | L65: 0 | N65: 0 | O65: ==0
A66: 68025be4cac355bcf689c356 | B66: 5 | D66: 0 | F66: 0 | G66: 25x18 | H66: 0 | I66: 0 | J66: 0 | K66: 3 | L66: 0 | M66: stuks | N66: 0 | O66: ==0
A67: 68025c03cac355bcf689c357 | B67: 1 | D67: 0 | F67: 0 | G67: 150x35,5 | H67: 0 | I67: 0 | J67: 0 | K67: 3 | L67: 0 | M67: stuks | N67: 0 | O67: ==0
A68: 6878eef989cba9c4ba692ace | B68: 1 | D68: 0 | F68: 0 | G68: 235 x 47 | H68: 0 | I68: 0 | J68: 0 | K68: 3 | L68: 0 | M68: stuks | N68: 0 | O68: ==0
A69: 6878ef2d89cba9c4ba692acf | B69: 1 | D69: 0 | F69: 0 | G69: 258,5 x 36,5 | H69: 0 | I69: 0 | J69: 0 | K69: 3 | L69: 0 | M69: stuks | N69: 0 | O69: ==0
A70: 68bad93386954bbeeed8b0a5 | B70: 1 | D70: 0 | F70: 0 | G70: 90 x 26 | H70: 0 | I70: 0 | J70: 0 | K70: 3 | L70: 0 | M70: stuks | N70: 0 | O70: ==0
A71: 68bad95a86954bbeeed8b0a6 | B71: 1 | D71: 0 | F71: 0 | G71: 64 x 26,5 | H71: 0 | I71: 0 | J71: 0 | K71: 3 | L71: 0 | M71: stuks | N71: 0 | O71: ==0
A72: 68c3caa12ae243776f752aa2 | B72: 1 | D72: 0 | F72: 0 | G72: 60 x 14,9 | H72: 0 | I72: 0 | J72: 0 | K72: 3 | L72: 0 | M72: stuks | N72: 0 | O72: ==0
A73: 68fb700cef6946862c8b4d55 | B73: 1 | D73: 0 | F73: 0 | G73: 210 x 62,5 | H73: 0 | I73: 0 | J73: 0 | K73: 3 | L73: 0 | M73: stuks | N73: 0 | O73: ==0
A74: 68fb80b60ff4160ed66b4da2 | B74: 1 | D74: 0 | F74: 0 | G74: 128,5 x 59,5 | H74: 0 | I74: 0 | J74: 0 | K74: 3 | L74: 0 | M74: stuks | N74: 0 | O74: ==0
N75: Total | O75: ==SUM(O2:O74)

Sheet borden_wit
A1: _id | B1: available | C1: calculation_type | D1: depth_cm | E1: format | F1: height_cm | G1: name | H1: price_per_meter | I1: price_per_piece | J1: price_per_square_meter | K1: thickness | L1: total_meter_per_rol | M1: unit | N1: width_cm | O1: subtotal
A2: 676521ea5ff93f7b6d3f921d | B2: 1 | C2: bord | F2: 30 | G2: 41 x 30 | J2: 4.58 | K2: 3 | M2: stuks | N2: 41 | O2: ==B2*(N2*F2/10000)*J2
A3: 676521ea5ff93f7b6d3f921e | B3: 1 | C3: bord | F3: 20 | G3: 28 x 20 | J3: 4.58 | K3: 3 | M3: stuks | N3: 28 | O3: ==B3*(N3*F3/10000)*J3
A4: 676521ea5ff93f7b6d3f921f | B4: 1 | C4: bord | F4: 29 | G4: 20 x 29 | J4: 4.58 | K4: 3 | M4: stuks | N4: 20 | O4: ==B4*(N4*F4/10000)*J4
A5: 676521ea5ff93f7b6d3f9220 | B5: 1 | C5: bord | F5: 28 | G5: 24,5 x 28 | J5: 4.58 | K5: 3 | M5: stuks | N5: 24.5 | O5: ==B5*(N5*F5/10000)*J5
A6: 676521eb5ff93f7b6d3f9221 | B6: 2 | C6: bord | F6: 28.5 | G6: 25,5 x 28,5 | J6: 4.58 | K6: 3 | M6: stuks | N6: 25.5 | O6: ==B6*(N6*F6/10000)*J6
A7: 676521eb5ff93f7b6d3f9222 | B7: 1 | C7: bord | F7: 24 | G7: 60 x 24 | J7: 4.58 | K7: 3 | M7: stuks | N7: 60 | O7: ==B7*(N7*F7/10000)*J7
A8: 676521eb5ff93f7b6d3f9223 | B8: 1 | C8: bord | F8: 52 | G8: 20 x 52 | J8: 4.58 | K8: 3 | M8: stuks | N8: 20 | O8: ==B8*(N8*F8/10000)*J8
A9: 676521eb5ff93f7b6d3f9224 | B9: 1 | C9: bord | F9: 30 | G9: 40 x 30 | J9: 4.58 | K9: 3 | M9: stuks | N9: 40 | O9: ==B9*(N9*F9/10000)*J9
A10: 676521eb5ff93f7b6d3f9225 | B10: 1 | C10: bord | F10: 25 | G10: 28 x 25 | J10: 4.58 | K10: 3 | M10: stuks | N10: 28 | O10: ==B10*(N10*F10/10000)*J10
A11: 676521eb5ff93f7b6d3f9226 | B11: 2 | C11: bord | F11: 15 | G11: 22 x 15 | J11: 4.58 | K11: 3 | M11: stuks | N11: 22 | O11: ==B11*(N11*F11/10000)*J11
A12: 676521eb5ff93f7b6d3f9227 | B12: 1 | C12: bord | F12: 19 | G12: 20 x 19 | J12: 4.58 | K12: 3 | M12: stuks | N12: 20 | O12: ==B12*(N12*F12/10000)*J12
A13: 676521eb5ff93f7b6d3f9228 | B13: 1 | C13: bord | F13: 20 | G13: 23 x 20 | J13: 4.58 | K13: 3 | M13: stuks | N13: 23 | O13: ==B13*(N13*F13/10000)*J13
... A86: 676521f35ff93f7b6d3f9276 | B86: 2 | C86: bord | F86: 21 | G86: 29x21 | J86: 4.58 | K86: 3 | M86: stuks | N86: 29 | O86: ==B86*(N86*F86/10000)*J86
A87: 677d504d4b75be395ab31728 | B87: 1 | D87: 0 | F87: 0 | G87: 44x51 | H87: 0 | I87: 0 | J87: 0 | K87: 1 | L87: 0 | M87: stuks | N87: 0 | O87: ==0
A88: 677d506b4b75be395ab31729 | B88: 1 | D88: 0 | F88: 0 | G88: 44x53,5 | H88: 0 | I88: 0 | J88: 0 | K88: 3 | L88: 0 | M88: stuks | N88: 0 | O88: ==0
A89: 677d508776407687ab1e9760 | B89: 1 | D89: 0 | F89: 0 | G89: 244x31 | H89: 0 | I89: 0 | J89: 0 | K89: 3 | L89: 0 | M89: stuks | N89: 0 | O89: ==0
A90: 678135632e2cbf8223441caf | B90: 1 | D90: 0 | F90: 0 | G90: 57X20 | H90: 0 | I90: 0 | J90: 0 | K90: 3 | L90: 0 | M90: stuks | N90: 0 | O90: ==0
A91: 678135792e2cbf8223441cb0 | B91: 4 | D91: 0 | F91: 0 | G91: 15X10 | H91: 0 | I91: 0 | J91: 0 | K91: 3 | L91: 0 | M91: stuks | N91: 0 | O91: ==0
A92: 678135932e2cbf8223441cb1 | B92: 1 | D92: 0 | F92: 0 | G92: 150X32 | H92: 0 | I92: 0 | J92: 0 | K92: 3 | L92: 0 | M92: stuks | N92: 0 | O92: ==0
A93: 679a4af9c3ca6900dbed1a82 | B93: 1 | D93: 0 | F93: 0 | G93: 50x47,5 | H93: 0 | I93: 0 | J93: 0 | K93: 3 | L93: 0 | M93: stuks | N93: 0 | O93: ==0
A94: 679a4b62c3ca6900dbed1a83 | B94: 2 | D94: 0 | F94: 0 | G94: 160x32,5 | H94: 0 | I94: 0 | J94: 0 | K94: 3 | L94: 0 | M94: stuks | N94: 0 | O94: ==0
A95: 679a4b86c3ca6900dbed1a84 | B95: 1 | D95: 0 | F95: 0 | G95: 150x31,5 | H95: 0 | I95: 0 | J95: 0 | K95: 3 | L95: 0 | M95: stuks | N95: 0 | O95: ==0
A96: 67c07ca6912df475d9349e1f | B96: 1 | D96: 0 | F96: 0 | G96: 158x69 | H96: 0 | I96: 0 | J96: 0 | K96: 6 | L96: 0 | M96: stuks | N96: 0 | O96: ==0
A97: 67c5c135591fcb41f3c8aced | B97: 1 | D97: 0 | F97: 0 | G97: 104x150 | H97: 0 | I97: 0 | J97: 0 | K97: 6 | L97: 0 | M97: stuks | N97: 0 | O97: ==0
A98: 67c5c191591fcb41f3c8acf0 | B98: 1 | D98: 0 | F98: 0 | G98: 100x20 | H98: 0 | I98: 0 | J98: 0 | K98: 3 | L98: 0 | M98: stuks | N98: 0 | O98: ==0
... A115: 684c1e3631b7795292daf1e4 | B115: 1 | D115: 0 | F115: 0 | G115: 100x31,5 | H115: 0 | I115: 0 | J115: 0 | K115: 3 | L115: 0 | M115: stuks | N115: 0 | O115: ==0
A116: 6852c4c6a5e5f18f8d705c06 | B116: 2 | D116: 0 | F116: 0 | G116: 50X50 | H116: 0 | I116: 0 | J116: 0 | K116: 3 | L116: 0 | N116: 0 | O116: ==0
A117: 685560486e642ee74f040742 | B117: 6 | D117: 0 | F117: 0 | G117: 30x17 | H117: 0 | I117: 0 | J117: 0 | K117: 3 | L117: 0 | N117: 0 | O117: ==0
A118: 685560b46e642ee74f040743 | B118: 1 | D118: 0 | F118: 0 | G118: 30x20 | H118: 0 | I118: 0 | J118: 0 | K118: 3 | L118: 0 | N118: 0 | O118: ==0
A119: 685560cc6e642ee74f040744 | B119: 4 | D119: 0 | F119: 0 | G119: 29x21,5 | H119: 0 | I119: 0 | J119: 0 | K119: 3 | L119: 0 | N119: 0 | O119: ==0
A120: 685d5ed146dfdea32dd73ac8 | B120: 1 | D120: 0 | F120: 0 | G120: 60,5x15 | H120: 0 | I120: 0 | J120: 0 | K120: 3 | L120: 0 | M120: stuks | N120: 0 | O120: ==0
A121: 6876608ea79629a80fa11224 | B121: 3 | D121: 0 | F121: 0 | G121: 15,5x255 | H121: 0 | I121: 0 | J121: 0 | K121: 3 | L121: 0 | N121: 0 | O121: ==0
A122: 687660cea79629a80fa11225 | B122: 1 | D122: 0 | F122: 0 | G122: 42,5 x 190 | H122: 0 | I122: 0 | J122: 0 | K122: 3 | L122: 0 | N122: 0 | O122: ==0
A123: 6877b5a9848f85a84b73b2ac | B123: 1 | D123: 0 | F123: 0 | G123: 105x16,5 | H123: 0 | I123: 0 | J123: 0 | K123: 3 | L123: 0 | M123: stuks | N123: 0 | O123: ==0
A124: 6877b5e9848f85a84b73b2ad | B124: 1 | D124: 0 | F124: 0 | G124: 105x36 | H124: 0 | I124: 0 | J124: 0 | K124: 3 | L124: 0 | M124: stuks | N124: 0 | O124: ==0
A125: 6877b633848f85a84b73b2ae | B125: 1 | D125: 0 | F125: 0 | G125: 150x33 | H125: 0 | I125: 0 | J125: 0 | K125: 3 | L125: 0 | M125: stuks | N125: 0 | O125: ==0
A126: 6878ef7489cba9c4ba692ad0 | B126: 1 | D126: 0 | F126: 0 | G126: 153,5 x 19 | H126: 0 | I126: 0 | J126: 0 | K126: 3 | L126: 0 | M126: stuks | N126: 0 | O126: ==0
A127: 6878ef9c89cba9c4ba692ad1 | B127: 1 | D127: 0 | F127: 0 | G127: 69,5 x 51 | H127: 0 | I127: 0 | J127: 0 | K127: 3 | L127: 0 | M127: stuks | N127: 0 | O127: ==0
A128: 6878efc989cba9c4ba692ad2 | B128: 1 | D128: 0 | F128: 0 | G128: 46 x 42,5 | H128: 0 | I128: 0 | J128: 0 | K128: 3 | L128: 0 | M128: stuks | N128: 0 | O128: ==0
...

Sheet borden_kanaalplaten
A1: _id | B1: available | C1: calculation_type | D1: depth_cm | E1: format | F1: height_cm | G1: name | H1: price_per_meter | I1: price_per_piece | J1: price_per_square_meter | K1: thickness | L1: total_meter_per_rol | M1: unit | N1: width_cm | O1: subtotal
A2: 676521e45ff93f7b6d3f91d3 | B2: 1 | C2: bord | F2: 200 | G2: 60 X 200 | J2: 12.5 | M2: stuks | N2: 60 | O2: ==B2*(N2*F2/10000)*J2
A3: 676521e45ff93f7b6d3f91d4 | B3: 1 | C3: bord | F3: 30.5 | G3: 200 X 30,5 | J3: 12.5 | M3: stuks | N3: 200 | O3: ==B3*(N3*F3/10000)*J3
A4: 676521e45ff93f7b6d3f91d5 | B4: 1 | C4: bord | F4: 45 | G4: 65 X 45 | J4: 12.5 | M4: stuks | N4: 65 | O4: ==B4*(N4*F4/10000)*J4
A5: 676521e55ff93f7b6d3f91d6 | B5: 6 | C5: bord | F5: 45 | G5: 125 X 45 | J5: 12.5 | M5: stuks | N5: 125 | O5: ==B5*(N5*F5/10000)*J5
A6: 676521e55ff93f7b6d3f91d7 | B6: 0 | C6: bord | F6: 250 | G6: 100 x 250 | J6: 12.5 | K6: 8 | M6: stuks | N6: 100 | O6: ==B6*(N6*F6/10000)*J6
A7: 676521e55ff93f7b6d3f91d8 | B7: 2 | C7: bord | F7: 50 | G7: 70 x 50 | J7: 12.5 | K7: 3 | M7: stuks | N7: 70 | O7: ==B7*(N7*F7/10000)*J7
A8: 67d9119da6b6a1ef37fb77f9 | B8: 1 | D8: 0 | F8: 0 | G8: 160x70 | H8: 0 | I8: 0 | J8: 0 | K8: 3 | L8: 0 | M8: stuks | N8: 0 | O8: ==0
A9: 67d911b2a6b6a1ef37fb77fa | B9: 1 | D9: 0 | F9: 0 | G9: 70x50 | H9: 0 | I9: 0 | J9: 0 | K9: 3 | L9: 0 | M9: stuks | N9: 0 | O9: ==0
A10: 68a4691c8c25aa187ca2b01b | B10: 1 | D10: 0 | F10: 0 | G10: 70 x 52,4 | H10: 0 | I10: 0 | J10: 0 | K10: 3 | L10: 0 | M10: stuks | N10: 0 | O10: ==0
A11: 68dba9debb15253d78adb249 | B11: 4 | D11: 0 | F11: 0 | G11: 50 x 40 | H11: 0 | I11: 0 | J11: 0 | K11: 4 | L11: 0 | M11: stuks | N11: 0 | O11: ==0
A12: 68e8c847c899505111675709 | B12: 8 | D12: 0 | F12: 0 | G12: 50 x 22 | H12: 0 | I12: 0 | J12: 0 | K12: 4 | L12: 0 | M12: stuks | N12: 0 | O12: ==0
N13: Total | O13: ==SUM(O2:O12)

Sheet borden_brushed_steel
A1: _id | B1: available | C1: calculation_type | D1: depth_cm | E1: format | F1: height_cm | G1: name | H1: price_per_meter | I1: price_per_piece | J1: price_per_square_meter | K1: thickness | L1: total_meter_per_rol | M1: unit | N1: width_cm | O1: subtotal
A2: 676521f35ff93f7b6d3f927a | B2: 1 | C2: bord | F2: 87 | G2: 150x87 | J2: 1.31 | K2: 3 | M2: stuks | N2: 150 | O2: ==B2*(N2*F2/10000)*J2
A3: 676521f35ff93f7b6d3f927b | B3: 1 | C3: bord | F3: 35 | G3: 215x35 | J3: 0.75 | K3: 3 | M3: stuks | N3: 215 | O3: ==B3*(N3*F3/10000)*J3
A4: 676521f35ff93f7b6d3f927c | B4: 1 | C4: bord | F4: 35 | G4: 175 x 35 | J4: 0.61 | K4: 3 | M4: stuks | N4: 175 | O4: ==B4*(N4*F4/10000)*J4
N5: Total | O5: ==SUM(O2:O4)

Sheet borden_plexiglas
A1: _id | B1: available | C1: calculation_type | D1: depth_cm | E1: format | F1: height_cm | G1: name | H1: price_per_meter | I1: price_per_piece | J1: price_per_square_meter | K1: thickness | L1: total_meter_per_rol | M1: unit | N1: width_cm | O1: subtotal
A2: 676521e55ff93f7b6d3f91de | B2: 7 | C2: bord | F2: 30 | G2: 30 x 30 | J2: 151.46 | K2: 7 | M2: stuks | N2: 30 | O2: ==B2*(N2*F2/10000)*J2
A3: 676521e55ff93f7b6d3f91df | B3: 7 | C3: bord | F3: 25 | G3: 30 x 25 | J3: 151.46 | K3: 7 | M3: stuks | N3: 30 | O3: ==B3*(N3*F3/10000)*J3
A4: 676521e65ff93f7b6d3f91e0 | B4: 1 | C4: bord | F4: 42 | G4: A3 | J4: 151.46 | K4: 7 | M4: stuks | N4: 29.7 | O4: ==B4*(N4*F4/10000)*J4
A5: 676521e65ff93f7b6d3f91e1 | B5: 3 | C5: bord | F5: 10 | G5: 30 x 10 | J5: 151.46 | K5: 7 | M5: stuks | N5: 30 | O5: ==B5*(N5*F5/10000)*J5
A6: 676521e65ff93f7b6d3f91e2 | B6: 1 | C6: bord | F6: 50 | G6: 70 x 50 | J6: 151.46 | K6: 5 | M6: stuks | N6: 70 | O6: ==B6*(N6*F6/10000)*J6
A7: 6841afabcbb82631b1709a2f | B7: 1 | D7: 0 | F7: 0 | G7: 205x63 | H7: 0 | I7: 0 | J7: 0 | K7: 3 | L7: 0 | M7: stuks | N7: 0 | O7: ==0
N8: Total | O8: ==SUM(O2:O7)

Sheet stock_rollup
A1: _id | B1: available | C1: calculation_type | D1: depth_cm | E1: format | F1: height_cm | G1: name | H1: price_per_meter | I1: price_per_piece | J1: price_per_square_meter | K1: thickness | L1: total_meter_per_rol | M1: unit | N1: width_cm | O1: subtotal
A2: 6765228a85d21deb735a1f8f | B2: 2 | C2: stuk | E2: 85cm | G2: Breed | I2: 63.64 | M2: stuks | O2: ==B2*I2
N3: Total | O3: ==SUM(O2:O2)

Sheet stock_snijfolie
A1: _id | B1: available | C1: calculation_type | D1: depth_cm | E1: format | F1: height_cm | G1: name | H1: price_per_meter | I1: price_per_piece | J1: price_per_square_meter | K1: thickness | L1: total_meter_per_rol | M1: unit | N1: width_cm | O1: subtotal
A2: 6765228585d21deb735a1f52 | B2: 25 | C2: rol_per_meter | G2: AVERY 700 GLOSS WHITE | H2: 6.32 | M2: M | O2: ==B2*H2
A3: 6765228585d21deb735a1f53 | B3: 1.5 | C3: rol_per_meter | G3: AVERY 709 OCEAN BLUE | H3: 6.88 | M3: M | O3: ==B3*H3
A4: 6765228585d21deb735a1f54 | B4: 0.75 | C4: rol_per_meter | G4: AVERY 711 FORREST GREEN | H4: 6.88 | M4: M | O4: ==B4*H4
A5: 6765228585d21deb735a1f56 | B5: 25 | C5: rol_per_meter | G5: AVERY 701 GLOSS BLACK | H5: 6.32 | M5: M | O5: ==B5*H5
A6: 6765228685d21deb735a1f57 | B6: 1.25 | C6: rol_per_meter | G6: AVERY 726 MEDIUM RED | H6: 6.88 | M6: M | O6: ==B6*H6
A7: 6765228685d21deb735a1f5e | B7: 1.25 | C7: rol_per_meter | G7: AVERY 770 RED | H7: 6.88 | M7: M | O7: ==B7*H7
A8: 6765228685d21deb735a1f5f | B8: 0.63 | C8: rol_per_meter | G8: AVERY 783 SCANDINAVIAN BLUE | H8: 6.88 | M8: M | O8: ==B8*H8
A9: 6765228685d21deb735a1f61 | B9: 8.5 | C9: rol_per_meter | G9: AVERY 941 COSMOS BLUE | H9: 18.25 | M9: M | O9: ==B9*H9
A10: 6765228785d21deb735a1f6a | B10: 2.8 | C10: rol_per_meter | G10: AVERY 708 COSMOS BLUE | H10: 0 | M10: M | O10: ==B10*H10
A11: 687fa0dbe96a679fee6eb554 | B11: 2.87 | D11: 0 | F11: 0 | G11: AVERY 770 RED | H11: 0 | I11: 0 | J11: 0 | K11: 0 | L11: 0 | M11: m | N11: 0 | O11: ==0
A12: 687fa1fee96a679fee6eb555 | B12: 1.71 | D12: 0 | F12: 0 | G12: AVERY 733 BLUE | H12: 0 | I12: 0 | J12: 0 | K12: 0 | L12: 0 | M12: m | N12: 0 | O12: ==0
A13: 687fa21ae96a679fee6eb556 | B13: 1.81 | D13: 0 | F13: 0 | G13: AVERY 733 BLUE | H13: 0 | I13: 0 | J13: 0 | K13: 0 | L13: 0 | M13: m | N13: 0 | O13: ==0
A14: 687fa246e96a679fee6eb557 | B14: 0.88 | D14: 0 | F14: 0 | G14: AVERY 783 SCANDINAVIAN BLUE | H14: 0 | I14: 0 | J14: 0 | K14: 0 | L14: 0 | M14: m | N14: 0 | O14: ==0
A15: 687fa270e96a679fee6eb558 | B15: 1.72 | D15: 0 | F15: 0 | G15: AVERY 783 SCANDINAVIAN BLUE | H15: 0 | I15: 0 | J15: 0 | K15: 0 | L15: 0 | M15: m | N15: 0 | O15: ==0
A16: 687fa2b3e96a679fee6eb559 | B16: 1.03 | D16: 0 | F16: 0 | G16: AVERY 726 MEDIUM RED | H16: 0 | I16: 0 | J16: 0 | K16: 0 | L16: 0 | M16: m | N16: 0 | O16: ==0
A17: 687fa353e96a679fee6eb55a | B17: 2.34 | D17: 0 | F17: 0 | G17: AVERY 910-01 ORANGE | H17: 0 | I17: 0 | J17: 0 | K17: 0 | L17: 0 | N17: 0 | O17: ==0
A18: 687fa50be96a679fee6eb55b | B18: 2.65 | D18: 0 | F18: 0 | G18: AVERY 842 TEAL | H18: 0 | I18: 0 | J18: 0 | K18: 0 | L18: 0 | M18: m | N18: 0 | O18: ==0
A19: 687fa527e96a679fee6eb55c | B19: 1.5 | D19: 0 | F19: 0 | G19: AVERY 842 TEAL | H19: 0 | I19: 0 | J19: 0 | K19: 0 | L19: 0 | M19: m | N19: 0 | O19: ==0
A20: 687fa545e96a679fee6eb55d | B20: 1.25 | D20: 0 | F20: 0 | G20: AVERY 842 TEAL | H20: 0 | I20: 0 | J20: 0 | K20: 0 | L20: 0 | M20: m | N20: 0 | O20: ==0
A21: 687fa5ace96a679fee6eb55e | B21: 0.81 | D21: 0 | F21: 0 | G21: AVERY 759 DARK GREY | H21: 0 | I21: 0 | J21: 0 | K21: 0 | L21: 0 | M21: m | N21: 0 | O21: ==0
A22: 687fa5c0e96a679fee6eb55f | B22: 0.86 | D22: 0 | F22: 0 | G22: AVERY 759 DARK GREY | H22: 0 | I22: 0 | J22: 0 | K22: 0 | L22: 0 | M22: m | N22: 0 | O22: ==0
A23: 687fa640e96a679fee6eb560 | B23: 4.3 | D23: 0 | F23: 0 | G23: AVERY 707 PRIMEROSE YELLOW | H23: 0 | I23: 0 | J23: 0 | K23: 0 | L23: 0 | M23: m | N23: 0 | O23: ==0
A24: 687fa6ade96a679fee6eb561 | B24: 1.62 | D24: 0 | F24: 0 | G24: AVERY 735-01 SILVER METALLIC | H24: 0 | I24: 0 | J24: 0 | K24: 0 | L24: 0 | M24: m | N24: 0 | O24: ==0
A25: 688091adb3031d56aff6ef9f | B25: 25 | D25: 0 | F25: 0 | G25: AVERY 730 MATT WHITE | H25: 0 | I25: 0 | J25: 0 | K25: 0 | L25: 0 | N25: 0 | O25: ==0
A26: 688091e5b3031d56aff6efa0 | B26: 25 | D26: 0 | F26: 0 | G26: AVERY 721 matt BLACK | H26: 0 | I26: 0 | J26: 0 | K26: 0 | L26: 0 | N26: 0 | O26: ==0
A27: 68809213b3031d56aff6efa1 | B27: 25 | D27: 0 | F27: 0 | G27: AVERY 735-01 SILVER METALLIC | H27: 0 | I27: 0 | J27: 0 | K27: 0 | L27: 0 | N27: 0 | O27: ==0
N28: Total | O28: ==SUM(O2:O27)

Sheet stock_interieurfolie
A1: _id | B1: available | C1: calculation_type | D1: depth_cm | E1: format | F1: height_cm | G1: name | H1: price_per_meter | I1: price_per_piece | J1: price_per_square_meter | K1: thickness | L1: total_meter_per_rol | M1: unit | N1: width_cm | O1: subtotal
A2: 6765228885d21deb735a1f7b | B2: 1.4 | C2: rol_per_meter | G2: Coverstyl NH10 Terrazo | H2: 18.65 | M2: M | O2: ==B2*H2
A3: 6765228885d21deb735a1f7c | B3: 3 | C3: rol_per_meter | G3: Coverstyl NE81 Black | H3: 17.49 | M3: M | O3: ==B3*H3
A4: 6765228885d21deb735a1f7d | B4: 0.93 | C4: rol_per_meter | G4: Coverstyl U50 marble stone | H4: 18.65 | M4: M | O4: ==B4*H4
A5: 6765228885d21deb735a1f7e | B5: 1.2 | C5: rol_per_meter | G5: Coverstyl U50 marble stone | H5: 18.65 | M5: M | O5: ==B5*H5
A6: 6765228985d21deb735a1f7f | B6: 1.4 | C6: rol_per_meter | G6: Coverstyl NH33 concrete pure | H6: 24.13 | M6: M | O6: ==B6*H6
N7: Total | O7: ==SUM(O2:O6)

Sheet stock_flex
A1: _id | B1: available | C1: calculation_type | D1: depth_cm | E1: format | F1: height_cm | G1: name | H1: price_per_meter | I1: price_per_piece | J1: price_per_square_meter | K1: thickness | L1: total_meter_per_rol | M1: unit | N1: width_cm | O1: subtotal
A2: 6765228a85d21deb735a1f90 | B2: 3 | C2: rol_per_meter | G2: Gele Flock | H2: 12.5 | M2: M | O2: ==B2*H2
A3: 6765228a85d21deb735a1f91 | B3: 0.4 | C3: rol_per_meter | G3: Oranje | H3: 6.21 | M3: M | O3: ==B3*H3
A4: 6765228a85d21deb735a1f92 | B4: 0.5 | C4: rol_per_meter | G4: Roze | H4: 6.21 | M4: M | O4: ==B4*H4
A5: 6765228a85d21deb735a1f93 | B5: 0.7 | C5: rol_per_meter | G5: Groen | H5: 6.21 | M5: M | O5: ==B5*H5
A6: 6765228a85d21deb735a1f94 | B6: 0.65 | C6: rol_per_meter | G6: Goud | H6: 6.21 | M6: M | O6: ==B6*H6
A7: 6765228a85d21deb735a1f95 | B7: 6 | C7: rol_per_meter | G7: Goud | H7: 6.21 | M7: M | O7: ==B7*H7
A8: 6765228a85d21deb735a1f96 | B8: 2 | C8: rol_per_meter | G8: Glow in the dark | H8: 12.1 | M8: M | O8: ==B8*H8
A9: 6765228a85d21deb735a1f97 | B9: 4 | C9: rol_per_meter | G9: Blauw | H9: 6.21 | M9: M | O9: ==B9*H9
A10: 6765228a85d21deb735a1f98 | B10: 5 | C10: rol_per_meter | G10: Rood | H10: 6.21 | M10: M | O10: ==B10*H10
A11: 6765228a85d21deb735a1f99 | B11: 3 | C11: rol_per_meter | G11: Fluo Groen | H11: 7.1 | M11: M | O11: ==B11*H11
A12: 6765228b85d21deb735a1f9a | B12: 4 | C12: rol_per_meter | G12: Donkerblauw | H12: 6.21 | M12: M | O12: ==B12*H12
A13: 6765228b85d21deb735a1f9b | B13: 2 | C13: rol_per_meter | G13: Zwart | H13: 6.21 | M13: M | O13: ==B13*H13
... A22: 6765228b85d21deb735a1fa4 | B22: 0.9 | C22: rol_per_meter | G22: roos glitter | H22: 10.41 | M22: M | O22: ==B22*H22
N23: Total | O23: ==SUM(O2:O22)

Sheet stock_printfolie
A1: _id | B1: available | C1: calculation_type | D1: depth_cm | E1: format | F1: height_cm | G1: name | H1: price_per_meter | I1: price_per_piece | J1: price_per_square_meter | K1: thickness | L1: total_meter_per_rol | M1: unit | N1: width_cm | O1: subtotal
A2: 6765228e85d21deb735a1fc5 | B2: 5.3 | C2: rol_per_square_meter | G2: Avery MPI 2000 1M37 | J2: 4.14 | M2: M | N2: 137 | O2: ==B2*(N2/100)*J2
A3: 6765228e85d21deb735a1fc6 | B3: 20.8 | C3: rol_per_square_meter | G3: Avery MPI 2000 1M60 | J3: 4.14 | M3: M | N3: 160 | O3: ==B3*(N3/100)*J3
A4: 6765228e85d21deb735a1fc7 | B4: 2 | C4: rol_per_square_meter | G4: Avery MPI 2004 1M37 | J4: 5.01 | M4: M | N4: 137 | O4: ==B4*(N4/100)*J4
A5: 6765228e85d21deb735a1fc8 | B5: 10 | C5: rol_per_square_meter | G5: Avery MPI 2006 1M37 | J5: 5.1 | M5: M | N5: 137 | O5: ==B5*(N5/100)*J5
A6: 6765228e85d21deb735a1fc9 | B6: 0 | C6: rol_per_square_meter | G6: Avery MPI 2020 matt 1m37 | M6: M | N6: 137 | O6: ==B6*(N6/100)*J6
A7: 6765228e85d21deb735a1fca | B7: 50 | C7: rol_per_square_meter | G7: Avery MPI 2040 transp gloss 1m37 | J7: 4.57 | M7: M | N7: 137 | O7: ==B7*(N7/100)*J7
A8: 6765228e85d21deb735a1fcb | B8: 24 | C8: rol_per_square_meter | G8: Avery MPI 2040 transp gloss 1m50 | J8: 4.57 | M8: M | N8: 150 | O8: ==B8*(N8/100)*J8
A9: 6765228e85d21deb735a1fcc | B9: 0 | C9: rol_per_square_meter | G9: Avery MPI 3000 1M37 | J9: 1.71 | M9: M | N9: 137 | O9: ==B9*(N9/100)*J9
A10: 6765228e85d21deb735a1fcd | B10: 43 | C10: rol_per_square_meter | G10: Avery MPI 3000 1M37 | J10: 1.71 | M10: M | N10: 137 | O10: ==B10*(N10/100)*J10
A11: 6765228e85d21deb735a1fce | B11: 15.5 | C11: total_rol_per_meter | G11: Spandoek Mesh 1M60 | I11: 262.4 | L11: 50 | M11: M | N11: 160 | O11: 0
A12: 6765228e85d21deb735a1fcf | B12: 5 | C12: total_rol_per_meter | G12: neschen 1m37 | I12: 250.69 | L12: 50 | M12: M | N12: 137 | O12: 0
A13: 6765228e85d21deb735a1fd0 | B13: 15 | C13: rol_per_square_meter | G13: One way vision 1m | J13: 14.29 | M13: M | N13: 100 | O13: ==B13*(N13/100)*J13
A14: 6765228e85d21deb735a1fd1 | B14: 40 | C14: rol_per_square_meter | G14: One way vision 1m37 | J14: 14.29 | M14: M | N14: 137 | O14: ==B14*(N14/100)*J14
A15: 6765228f85d21deb735a1fd2 | B15: 3 | C15: rol_per_square_meter | G15: Avery mpi 1105 1m52 | J15: 11.2 | M15: M | N15: 152 | O15: ==B15*(N15/100)*J15
A16: 6765228f85d21deb735a1fd3 | B16: 11 | C16: total_rol_per_meter | G16: 3m transparant casting 1m37 | I16: 435.8 | L16: 25 | M16: M | N16: 137 | O16: 0
A17: 6765228f85d21deb735a1fd4 | B17: 30 | C17: total_rol_per_meter | G17: Spandoek jet550 1m37 | I17: 213.98 | L17: 30 | M17: M | N17: 137 | O17: 0
A18: 6765228f85d21deb735a1fd5 | B18: 50 | C18: rol_per_square_meter | G18: Avery mpi 3000 1M37 | J18: 1.71 | M18: M | N18: 137 | O18: ==B18*(N18/100)*J18
A19: 6765228f85d21deb735a1fd6 | B19: 0 | C19: rol_per_square_meter | G19: AVERY MPI 3000 1M37 | J19: 1.71 | M19: M | N19: 137 | O19: ==B19*(N19/100)*J19
A20: 6765228f85d21deb735a1fd7 | B20: 19 | C20: rol_per_square_meter | G20: Avery mpi 1105 1M52 | J20: 11.2 | M20: M | N20: 152 | O20: ==B20*(N20/100)*J20
A21: 6765228f85d21deb735a1fd9 | B21: 2.5 | C21: total_rol_per_meter | G21: Spandoek jet550 1m37 | I21: 213.98 | L21: 30 | M21: M | N21: 137 | O21: 0
A22: 6765228f85d21deb735a1fda | B22: 1.7 | C22: total_rol_per_meter | G22: Spandoek jet550 1m37 | I22: 213.98 | L22: 30 | M22: M | N22: 137 | O22: 0
A23: 6765228f85d21deb735a1fdb | B23: 2 | C23: total_rol_per_meter | G23: Spandoek jet550 1m37 | I23: 213.98 | L23: 30 | M23: M | N23: 137 | O23: 0
A24: 6765228f85d21deb735a1fdc | B24: 1.5 | C24: total_rol_per_meter | G24: Spandoek jet550 1m37 | I24: 213.98 | L24: 30 | M24: M | N24: 137 | O24: 0
A25: 6765228f85d21deb735a1fdd | B25: 40.5 | C25: rol_per_square_meter | G25: Canvas 1m37 | M25: M | N25: 137 | O25: ==B25*(N25/100)*J25
A26: 6765228f85d21deb735a1fde | B26: 26 | C26: rol_per_square_meter | G26: HEXIS HIGHTAC WALL | M26: M | N26: 137 | O26: ==B26*(N26/100)*J26
A27: 6765229085d21deb735a1fdf | B27: 0 | C27: rol_per_square_meter | G27: Avery mpi 3004 1M37 | M27: M | N27: 137 | O27: ==B27*(N27/100)*J27
A28: 6765229085d21deb735a1fe0 | B28: 3 | C28: rol_per_square_meter | G28: Avery mpi 1105 1m52 | M28: M | N28: 152 | O28: ==B28*(N28/100)*J28
A29: 6765229085d21deb735a1fe1 | B29: 45 | C29: rol_per_square_meter | G29: Avery MPI 2000 1M37 | J29: 4.14 | M29: M | N29: 137 | O29: ==B29*(N29/100)*J29
A30: 6765229085d21deb735a1fe2 | B30: 8 | C30: rol_per_square_meter | G30: Avery MPI 2000 1M60 | J30: 4.14 | M30: M | N30: 160 | O30: ==B30*(N30/100)*J30
A31: 6765229085d21deb735a1fe3 | B31: 7 | C31: rol_per_square_meter | G31: Avery MPI 2000 1M60 | J31: 4.14 | M31: M | N31: 160 | O31: ==B31*(N31/100)*J31
A32: 6780d319f17ffae576026ce8 | B32: 3 | D32: 0 | F32: 0 | G32: Roll-up 1M | H32: 0 | I32: 0 | J32: 0 | K32: 0 | L32: 0 | N32: 0 | O32: ==0
A33: 687f44e5105ffa8e29b24c8c | B33: 5 | D33: 0 | F33: 0 | G33: AVERY MPI 2000 1M60 | H33: 0 | I33: 0 | J33: 0 | K33: 0 | L33: 0 | N33: 0 | O33: ==0
A34: 687f465b105ffa8e29b24c8d | B34: 50 | D34: 0 | F34: 0 | G34: Avery MPI 2000 1M37 | H34: 0 | I34: 0 | J34: 0 | K34: 0 | L34: 0 | N34: 0 | O34: ==0
A35: 687f46fa105ffa8e29b24c8e | B35: 9 | D35: 0 | F35: 0 | G35: neschen 1m37 | H35: 0 | I35: 0 | J35: 0 | K35: 0 | L35: 0 | N35: 0 | O35: ==0
N36: Total | O36: ==SUM(O2:O35)

Sheet stock_swf
A1: _id | B1: available | C1: calculation_type | D1: depth_cm | E1: format | F1: height_cm | G1: name | H1: price_per_meter | I1: price_per_piece | J1: price_per_square_meter | K1: thickness | L1: total_meter_per_rol | M1: unit | N1: width_cm | O1: subtotal
A2: 6765228b85d21deb735a1fa5 | B2: 0 | C2: rol_per_meter | G2: Avery Gloss Grey | H2: 0 | M2: M | O2: ==B2*H2
A3: 6765228b85d21deb735a1fa6 | B3: 0 | C3: rol_per_meter | G3: Avery SWF Brons Grey Gloss | H3: 29.49 | M3: M | O3: ==B3*H3
A4: 6765228b85d21deb735a1fa7 | B4: 0 | C4: rol_per_meter | G4: Avery SWF Cardine Red | H4: 29.49 | M4: M | O4: ==B4*H4
A5: 6765228c85d21deb735a1fa8 | B5: 0 | C5: rol_per_meter | G5: Avery SWF Dark Blue Metallic | H5: 29.49 | M5: M | O5: ==B5*H5
A6: 6765228c85d21deb735a1fa9 | B6: 3.9 | C6: rol_per_meter | G6: Avery SWF gloss black | H6: 29.49 | M6: M | O6: ==B6*H6
A7: 6765228c85d21deb735a1faa | B7: 1.09 | C7: rol_per_meter | G7: Avery SWF gloss black | H7: 29.49 | M7: M | O7: ==B7*H7
A8: 6765228c85d21deb735a1fab | B8: 1.96 | C8: rol_per_meter | G8: Avery SWF gloss black | H8: 29.49 | M8: M | O8: ==B8*H8
A9: 6765228c85d21deb735a1fac | B9: 3.47 | C9: rol_per_meter | G9: Avery SWF gloss black | H9: 29.49 | M9: M | O9: ==B9*H9
A10: 6765228c85d21deb735a1fad | B10: 0 | C10: rol_per_meter | G10: Avery SWF Gloss Metallic Passion Red | H10: 29.49 | M10: M | O10: ==B10*H10
A11: 6765228c85d21deb735a1fae | B11: 0 | C11: rol_per_meter | G11: Avery SWF Gloss Soft Red | H11: 29.49 | M11: M | O11: ==B11*H11
A12: 6765228c85d21deb735a1faf | B12: 0 | C12: rol_per_meter | G12: Avery SWF Gloss White | H12: 29.49 | M12: M | O12: ==B12*H12
A13: 6765228c85d21deb735a1fb0 | B13: 0 | C13: rol_per_meter | G13: Avery SWF Grass Green | H13: 29.49 | M13: M | O13: ==B13*H13
... A16: 6765228c85d21deb735a1fb3 | B16: 0 | C16: rol_per_meter | G16: Avery SWF Light Blue | H16: 29.49 | M16: M | O16: ==B16*H16
A17: 6765228c85d21deb735a1fb4 | B17: 1.68 | C17: rol_per_meter | E17: 152 | G17: Avery SWF Matte Black | H17: 29.19 | M17: M | O17: ==B17*H17
A18: 6765228d85d21deb735a1fb5 | B18: 0 | C18: rol_per_meter | G18: Avery SWF Matte Black | H18: 29.49 | M18: M | O18: ==B18*H18
A19: 6765228d85d21deb735a1fb6 | B19: 0 | C19: rol_per_meter | G19: Avery SWF Matte Black | H19: 29.49 | M19: M | O19: ==B19*H19
A20: 6765228d85d21deb735a1fb7 | B20: 0 | C20: rol_per_meter | G20: Avery SWF Matte Black | H20: 29.49 | M20: M | O20: ==B20*H20
A21: 6765228d85d21deb735a1fb8 | B21: 0 | C21: rol_per_meter | G21: Avery SWF Matte Metallic Gunmetal | H21: 29.49 | M21: M | O21: ==B21*H21
A22: 6765228d85d21deb735a1fb9 | B22: 2.02 | C22: rol_per_meter | G22: Avery SWF Matte White | H22: 29.49 | M22: M | O22: ==B22*H22
A23: 6765228d85d21deb735a1fba | B23: 0 | C23: rol_per_meter | G23: Avery SWF Red Chrome | H23: 121.89 | M23: M | O23: ==B23*H23
A24: 6765228d85d21deb735a1fbb | B24: 0 | C24: rol_per_meter | G24: Avery SWF Red Chrome | H24: 121.89 | M24: M | O24: ==B24*H24
A25: 6765228d85d21deb735a1fbc | B25: 0 | C25: rol_per_meter | G25: Avery SWF Satin White | H25: 29.49 | M25: M | O25: ==B25*H25
A26: 6765228d85d21deb735a1fbd | B26: 0 | C26: rol_per_meter | G26: Brushed Steel | H26: 52.63 | M26: M | O26: ==B26*H26
A27: 6765228d85d21deb735a1fbe | B27: 3.5 | C27: rol_per_meter | G27: Hexis Fluo Groen | H27: 81.55 | M27: M | O27: ==B27*H27
A28: 6765228d85d21deb735a1fbf | B28: 5 | C28: rol_per_meter | G28: Hexis Gloss Light Blue | H28: 81.55 | M28: M | O28: ==B28*H28
A29: 6765228d85d21deb735a1fc0 | B29: 0 | C29: rol_per_meter | G29: Hexis oranje | H29: 81.55 | M29: M | O29: ==B29*H29
... A33: 6765228e85d21deb735a1fc4 | B33: 20 | C33: rol_per_meter | G33: Xpell | H33: 0 | M33: M | O33: ==B33*H33
A34: 68808502d0d8dc93cc8ae28f | B34: 0.9 | D34: 0 | F34: 0 | G34: Avery SWF Gloss Metallic gold | H34: 0 | I34: 0 | J34: 0 | K34: 0 | L34: 0 | M34: m | N34: 0 | O34: ==0
A35: 6880931fb3031d56aff6efa2 | B35: 3.02 | D35: 0 | F35: 0 | G35: Avery SWF Khaki Matte | H35: 0 | I35: 0 | J35: 0 | K35: 0 | L35: 0 | M35: m | N35: 0 | O35: ==0
A36: 688093a3b3031d56aff6efa3 | B36: 4.81 | D36: 0 | F36: 0 | G36: Avery SWF Satin Khaki | H36: 0 | I36: 0 | J36: 0 | K36: 0 | L36: 0 | M36: m | N36: 0 | O36: ==0
A37: 68809435b3031d56aff6efa4 | B37: 3.02 | D37: 0 | F37: 0 | G37: Avery SWF Satin Black | H37: 0 | I37: 0 | J37: 0 | K37: 0 | L37: 0 | M37: m | N37: 0 | O37: ==0
A38: 68809474b3031d56aff6efa5 | B38: 2.67 | D38: 0 | F38: 0 | G38: Avery SWF Gloss Yellow-O | H38: 0 | I38: 0 | J38: 0 | K38: 0 | L38: 0 | M38: m | N38: 0 | O38: ==0
N39: Total | O39: ==SUM(O2:O38)

Sheet stock_allerlei
A1: _id | B1: available | C1: calculation_type | D1: depth_cm | E1: format | F1: height_cm | G1: name | H1: price_per_meter | I1: price_per_piece | J1: price_per_square_meter | K1: thickness | L1: total_meter_per_rol | M1: unit | N1: width_cm | O1: subtotal
A2: 6765229085d21deb735a1fe4 | B2: 4 | C2: stuk | G2: Ontvetter | I2: 14.65 | M2: fles | O2: ==B2*I2
A3: 6765229085d21deb735a1fe5 | B3: 9 | C3: stuk | G3: lijmverwijderaar | I3: 22.815 | O3: ==B3*I3
A4: 6765229085d21deb735a1fe6 | B4: 32 | C4: stuk | G4: schilderstape | I4: 2.69 | O4: ==B4*I4
A5: 6765229085d21deb735a1fe7 | B5: 9 | C5: stuk | G5: zwarte ductape | I5: 4.5 | O5: ==B5*I5
A6: 6765229085d21deb735a1fe8 | B6: 26 | C6: stuk | G6: castaar tape | I6: 6.51 | O6: ==B6*I6
A7: 6765229085d21deb735a1fe9 | B7: 26 | C7: stuk | G7: bruine tape | I7: 1.12 | O7: ==B7*I7
A8: 687f5d967eb20c090720da58 | B8: 5 | D8: 0 | F8: 0 | G8: Beton WEBER 25Kg | H8: 0 | I8: 0 | J8: 0 | K8: 0 | L8: 0 | M8: stuks | N8: 0 | O8: ==0
N9: Total | O9: ==SUM(O2:O8)

Sheet stock_magneetfolie
A1: _id | B1: available | C1: calculation_type | D1: depth_cm | E1: format | F1: height_cm | G1: name | H1: price_per_meter | I1: price_per_piece | J1: price_per_square_meter | K1: thickness | L1: total_meter_per_rol | M1: unit | N1: width_cm | O1: subtotal
A2: 6765228985d21deb735a1f80 | B2: 2 | C2: rol_per_meter | G2: Magneetfolie 1m | H2: 10.55 | M2: M | O2: ==B2*H2
A3: 6765228985d21deb735a1f81 | B3: 0 | C3: rol_per_meter | G3: Magneetfolie 1m | H3: 10.55 | M3: M | O3: ==B3*H3
A4: 6765228985d21deb735a1f82 | B4: 1.3 | C4: rol_per_meter | G4: Magneetfolie 0,62m | H4: 10.55 | M4: M | O4: ==B4*H4
N5: Total | O5: ==SUM(O2:O4)

Sheet stock_buizen
A1: _id | B1: available | C1: calculation_type | D1: depth_cm | E1: format | F1: height_cm | G1: name | H1: price_per_meter | I1: price_per_piece | J1: price_per_square_meter | K1: thickness | L1: total_meter_per_rol | M1: unit | N1: width_cm | O1: subtotal
A2: 6765228785d21deb735a1f6f | B2: 4 | C2: stuk | E2: 300 cm | G2: Zwart metaal | I2: 45.75 | M2: stuks | O2: ==B2*I2
A3: 6765228785d21deb735a1f70 | B3: 1 | C3: stuk | E3: 300 | G3: Grijs Alva | I3: 21.75 | M3: stuks | O3: ==B3*I3
A4: 6765228885d21deb735a1f71 | B4: 6 | C4: stuk | E4: 250 | G4: Grijs Alva | I4: 17.98 | M4: stuks | O4: ==B4*I4
A5: 6765228885d21deb735a1f73 | B5: 1 | C5: stuk | E5: 190 | G5: Grijs Alva | I5: 14.39 | M5: stuks | O5: ==B5*I5
A6: 6765228885d21deb735a1f74 | B6: 6 | C6: stuk | G6: Leuningdragers Grijs Metaal | I6: 6.37 | M6: stuks | O6: ==B6*I6
A7: 6765228885d21deb735a1f75 | B7: 0 | C7: stuk | G7: T-stuk Grijs Metaal | I7: 0 | M7: stuks | O7: ==B7*I7
A8: 6765228885d21deb735a1f76 | B8: 2 | C8: stuk | G8: Koppelstuk Grijs Metaal | I8: 5.61 | M8: stuks | O8: ==B8*I8
A9: 6765228885d21deb735a1f77 | B9: 1 | C9: stuk | G9: Voetstukken Grijs Metaal | I9: 2.49 | M9: stuks | O9: ==B9*I9
A10: 6765228885d21deb735a1f78 | B10: 13 | C10: stuk | G10: Leuningdragers Zwart Metaal | I10: 5.25 | M10: stuks | O10: ==B10*I10
A11: 6765228885d21deb735a1f79 | B11: 2 | C11: stuk | G11: 90° Zwart Metaal | I11: 5.77 | M11: stuks | O11: ==B11*I11
A12: 6765228885d21deb735a1f7a | B12: 0 | C12: stuk | G12: 90° Grijs Metaal | I12: 3.53 | M12: stuks | O12: ==B12*I12
N13: Total | O13: ==SUM(O2:O12)

Sheet stock_zandstraal
A1: _id | B1: available | C1: calculation_type | D1: depth_cm | E1: format | F1: height_cm | G1: name | H1: price_per_meter | I1: price_per_piece | J1: price_per_square_meter | K1: thickness | L1: total_meter_per_rol | M1: unit | N1: width_cm | O1: subtotal
A2: 6765228985d21deb735a1f83 | B2: 4.5 | C2: rol_per_meter | E2: 123 | G2: Aslan Dry Apply EL 300 | M2: M | O2: ==B2*H2
A3: 6765228985d21deb735a1f84 | C3: rol_per_meter | G3: Aslan Dry Apply EL 300 | M3: M | O3: ==B3*H3
A4: 6765228985d21deb735a1f85 | B4: 0 | C4: rol_per_meter | G4: Aslan PrintSilverEtched DryApply DFL 302 | H4: 14.17 | M4: M | O4: ==B4*H4
A5: 6765228985d21deb735a1f86 | B5: 0 | C5: rol_per_meter | G5: Aslan PrintSilverEtched DryApply DFL 302 | H5: 14.17 | M5: M | O5: ==B5*H5
A6: 6765228985d21deb735a1f87 | B6: 2 | C6: rol_per_meter | E6: 123 | G6: Hexis Edged glass 1m23 | H6: 4.66 | M6: M | O6: ==B6*H6
A7: 6765228985d21deb735a1f88 | B7: 30 | C7: rol_per_meter | E7: 123 | G7: Hexis Edged glass 1m23 | H7: 4.66 | M7: M | O7: ==B7*H7
A8: 6765228985d21deb735a1f89 | B8: 0 | C8: rol_per_meter | G8: Hexis Edged glass 1m23 | H8: 4.66 | M8: M | O8: ==B8*H8
A9: 6765228985d21deb735a1f8a | B9: 0 | C9: rol_per_meter | G9: Hexis Edged glass 1m23 | H9: 4.66 | M9: M | O9: ==B9*H9
A10: 6765228985d21deb735a1f8b | B10: 0 | C10: rol_per_meter | G10: Hexis Edged glass 1m23 | H10: 4.66 | M10: M | O10: ==B10*H10
A11: 6765228a85d21deb735a1f8c | B11: 10 | C11: rol_per_meter | E11: 152 | G11: Hexis Edged glass 1m50 | H11: 5.45 | M11: M | O11: ==B11*H11
A12: 6765228a85d21deb735a1f8d | B12: 2.24 | C12: rol_per_meter | E12: 152 | G12: Hexis Edged glass 1m50 | H12: 5.45 | M12: M | O12: ==B12*H12
A13: 6765228a85d21deb735a1f8e | B13: 0 | C13: rol_per_meter | G13: Hexis Edged glass 1m50 | H13: 5.45 | M13: M | O13: ==B13*H13
N14: Total | O14: ==SUM(O2:O13)

Sheet stock_rekkers
A1: _id | B1: available | C1: calculation_type | D1: depth_cm | E1: format | F1: height_cm | G1: name | H1: price_per_meter | I1: price_per_piece | J1: price_per_square_meter | K1: thickness | L1: total_meter_per_rol | M1: unit | N1: width_cm | O1: subtotal
A2: 6765228785d21deb735a1f6b | B2: 370 | C2: stuk | E2: 25cm | G2: Rekkers 25cm | I2: 0.82 | M2: stuks | O2: ==B2*I2
A3: 6765228785d21deb735a1f6c | B3: 234 | C3: stuk | E3: 20cm | G3: Rekkers 20cm | I3: 0.82 | M3: stuks | O3: ==B3*I3
A4: 6765228785d21deb735a1f6d | B4: 332 | C4: stuk | E4: 20cm | G4: Rekkers 20cm | I4: 0.82 | M4: stuks | O4: ==B4*I4
A5: 6765228785d21deb735a1f6e | B5: 0 | C5: stuk | G5: Strips 360 x 4,8mm | I5: 0.82 | M5: stuks | O5: ==B5*I5
N6: Total | O6: ==SUM(O2:O5)

Sheet TOTALS
A1: Database | B1: Category | C1: Total
A2: borden | B2: afstandshouder | C2: =='borden_afstandshouder'!O6
A3: borden | B3: hout | C3: =='borden_hout'!O6
A4: borden | B4: plexi_opaal | C4: =='borden_plexi_opaal'!O3
A5: borden | B5: forex_zwart | C5: =='borden_forex_zwart'!P51
A6: borden | B6: forex_wit | C6: =='borden_forex_wit'!O63
A7: borden | B7: zwart | C7: =='borden_zwart'!O75
A8: borden | B8: wit | C8: =='borden_wit'!O153
A9: borden | B9: kanaalplaten | C9: =='borden_kanaalplaten'!O13
A10: borden | B10: brushed_steel | C10: =='borden_brushed_steel'!O5
A11: borden | B11: plexiglas | C11: =='borden_plexiglas'!O8
A12: stock | B12: rollup | C12: =='stock_rollup'!O3
A13: stock | B13: snijfolie | C13: =='stock_snijfolie'!O28
A14: stock | B14: interieurfolie | C14: =='stock_interieurfolie'!O7
A15: stock | B15: flex | C15: =='stock_flex'!O23
A16: stock | B16: printfolie | C16: =='stock_printfolie'!O36
A17: stock | B17: swf | C17: =='stock_swf'!O39
A18: stock | B18: allerlei | C18: =='stock_allerlei'!O9
A19: stock | B19: magneetfolie | C19: =='stock_magneetfolie'!O5
A20: stock | B20: buizen | C20: =='stock_buizen'!O13
A21: stock | B21: zandstraal | C21: =='stock_zandstraal'!O14
A22: stock | B22: rekkers | C22: =='stock_rekkers'!O6
A23: GRAND TOTAL | C23: ==SUM(C2:C22)
